Workbook

Sheet RESUMEN
A1: ID | B1: Event | C1: Est | D1: Year | E1: Month | F1: Day | G1: Hour | H1: Min | I1: Seg | J1: Lat Ev [°] | K1: Long Ev [°] | L1: Mag | M1: Depth [km] | N1: Lat Est [°] | O1: Long Est [°] | P1: Elevación [m] | Q1: Vs30 [m/s] | R1: F0 [Hz] | S1: str1 | T1: dip1 | U1: rake1 | V1: str2 | W1: dip2 | X1: rake2 | Y1: Repi [km] | Z1: Rhyp [km] | AA1: Rrup calc [km] | AB1: ID_name | AC1: ID_EST | AD1: ID_EV | AE1: tec_env | AF1: A0 | AG1: L [km] | AH1: W [km]
A2: 1 | B2: 2012-03-03T11-1-47_Mw_5,6 | C2: GO04 | D2: 2012 | E2: 3 | F2: 3 | G2: 11 | H2: 1 | I2: 47 | J2: -30.189 | K2: -71.448 | L2: 5.6 | M2: 34.6 | N2: -30.1727 | O2: -70.7993 | P2: 0 | Q2: 405 | R2: 1.64 | S2: 179 | T2: 23 | U2: 88 | V2: 1 | W2: 67 | X2: 91 | Y2: 62.502889 | Z2: 71.440683 | AA2: 98.935 | AB2: ID_1 | AC2: 1 | AD2: =_xlfn.XLOOKUP(B2,EVENTOS!B:B,EVENTOS!M:M,"--",0,1) -> 1 | AE2: 1 | AF2: =_xlfn.XLOOKUP(C2,ESTACIONES!B:B,ESTACIONES!N:N,0,0,1) -> 5.4872095 | AG2: =_xlfn.XLOOKUP(A2,'L y W'!A:A,'L y W'!B:B,0,0,1) -> 5.564165 | AH2: =_xlfn.XLOOKUP(A2,'L y W'!A:A,'L y W'!C:C,0,0,1) -> 5.8479008
A3: 10 | B3: 2012-04-01T7-31-36_Mw_5,2 | C3: PB06 | D3: 2012 | E3: 4 | F3: 1 | G3: 7 | H3: 31 | I3: 36 | J3: -23.056 | K3: -69.316 | L3: 5.2 | M3: 93.8 | N3: -22.7058 | O3: -69.57188 | P3: 0 | Q3: 736 | R3: 7.94 | S3: 260 | T3: 48 | U3: -18 | V3: 2 | W3: 77 | X3: -137 | Y3: 46.834151 | Z3: 104.84216 | AA3: 127.845 | AB3: ID_10 | AC3: 2 | AD3: =_xlfn.XLOOKUP(B3,EVENTOS!B:B,EVENTOS!M:M,"--",0,1) -> 2 | AE3: 2 | AF3: =_xlfn.XLOOKUP(C3,ESTACIONES!B:B,ESTACIONES!N:N,0,0,1) -> 1.793958 | AG3: =_xlfn.XLOOKUP(A3,'L y W'!A:A,'L y W'!B:B,0,0,1) -> 0 | AH3: =_xlfn.XLOOKUP(A3,'L y W'!A:A,'L y W'!C:C,0,0,1) -> 0
A4: 100 | B4: 2014-03-16T21-16-29_Mw_6,7 | C4: T03A | D4: 2014 | E4: 3 | F4: 16 | G4: 21 | H4: 16 | I4: 29 | J4: -19.965 | K4: -70.814 | L4: 6.7 | M4: 20.6 | N4: -20.23034 | O4: -70.14592 | P4: 0 | Q4: 635 | R4: 7.01 | S4: 284 | T4: 26 | U4: 54 | V4: 144 | W4: 69 | X4: 106 | Y4: 75.793021 | Z4: 78.542613 | AA4: 64.116982 | AB4: ID_100 | AC4: 3 | AD4: =_xlfn.XLOOKUP(B4,EVENTOS!B:B,EVENTOS!M:M,"--",0,1) -> 3 | AE4: 1 | AF4: =_xlfn.XLOOKUP(C4,ESTACIONES!B:B,ESTACIONES!N:N,0,0,1) -> 6.1460543 | AG4: =_xlfn.XLOOKUP(A4,'L y W'!A:A,'L y W'!B:B,0,0,1) -> 26.351176 | AH4: =_xlfn.XLOOKUP(A4,'L y W'!A:A,'L y W'!C:C,0,0,1) -> 17.599487
A5: 1009 | B5: 2015-09-17T1-41-5_Mw_6,5 | C5: GO04 | D5: 2015 | E5: 9 | F5: 17 | G5: 1 | H5: 41 | I5: 5 | J5: -31.113 | K5: -71.651 | L5: 6.5 | M5: 49.5 | N5: -30.1727 | O5: -70.7993 | P5: 0 | Q5: 405 | R5: 1.64 | S5: -- | T5: -- | U5: -- | V5: -- | W5: -- | X5: -- | Y5: 132.40902 | Z5: 141.35911 | AA5: 127.96 | AB5: ID_1009 | AC5: 1 | AD5: =_xlfn.XLOOKUP(B5,EVENTOS!B:B,EVENTOS!M:M,"--",0,1) -> 4 | AE5: 1 | AF5: =_xlfn.XLOOKUP(C5,ESTACIONES!B:B,ESTACIONES!N:N,0,0,1) -> 5.4872095 | AG5: =_xlfn.XLOOKUP(A5,'L y W'!A:A,'L y W'!B:B,0,0,1) -> #N/A | AH5: =_xlfn.XLOOKUP(A5,'L y W'!A:A,'L y W'!C:C,0,0,1) -> #N/A
A6: 101 | B6: 2014-03-16T21-16-29_Mw_6,7 | C6: T06A | D6: 2014 | E6: 3 | F6: 16 | G6: 21 | H6: 16 | I6: 29 | J6: -19.965 | K6: -70.814 | L6: 6.7 | M6: 20.6 | N6: -20.2142 | O6: -70.13789 | P6: 0 | Q6: 276 | R6: 1.67 | S6: 284 | T6: 26 | U6: 54 | V6: 144 | W6: 69 | X6: 106 | Y6: 75.903698 | Z6: 78.649421 | AA6: 64.404747 | AB6: ID_101 | AC6: 4 | AD6: =_xlfn.XLOOKUP(B6,EVENTOS!B:B,EVENTOS!M:M,"--",0,1) -> 3 | AE6: 1 | AF6: =_xlfn.XLOOKUP(C6,ESTACIONES!B:B,ESTACIONES!N:N,0,0,1) -> 1.8913069 | AG6: =_xlfn.XLOOKUP(A6,'L y W'!A:A,'L y W'!B:B,0,0,1) -> 26.351176 | AH6: =_xlfn.XLOOKUP(A6,'L y W'!A:A,'L y W'!C:C,0,0,1) -> 17.599487
A7: 1017 | B7: 2015-09-17T10-12-53_Mw_5,3 | C7: C10O | D7: 2015 | E7: 9 | F7: 17 | G7: 10 | H7: 12 | I7: 53 | J7: -30.536 | K7: -71.632 | L7: 5.3 | M7: 29.7 | N7: -30.23387 | O7: -71.08159 | P7: 1032 | Q7: 517 | R7: 6.5 | S7: -- | T7: -- | U7: -- | V7: -- | W7: -- | X7: -- | Y7: 62.612441 | Z7: 69.747929 | AA7: 69.747929 | AB7: ID_1017 | AC7: 5 | AD7: =_xlfn.XLOOKUP(B7,EVENTOS!B:B,EVENTOS!M:M,"--",0,1) -> 5 | AE7: 1 | AF7: =_xlfn.XLOOKUP(C7,ESTACIONES!B:B,ESTACIONES!N:N,0,0,1) -> 2.3356473 | AG7: =_xlfn.XLOOKUP(A7,'L y W'!A:A,'L y W'!B:B,0,0,1) -> #N/A | AH7: =_xlfn.XLOOKUP(A7,'L y W'!A:A,'L y W'!C:C,0,0,1) -> #N/A
A8: 1018 | B8: 2015-09-17T10-31-25_Mw_5,0 | C8: C10O | D8: 2015 | E8: 9 | F8: 17 | G8: 10 | H8: 31 | I8: 25 | J8: -30.933 | K8: -71.459 | L8: 5 | M8: 51.1 | N8: -30.23387 | O8: -71.08159 | P8: 1032 | Q8: 517 | R8: 6.5 | S8: -- | T8: -- | U8: -- | V8: -- | W8: -- | X8: -- | Y8: 85.54396 | Z8: 100.17742 | AA8: 100.17742 | AB8: ID_1018 | AC8: 5 | AD8: =_xlfn.XLOOKUP(B8,EVENTOS!B:B,EVENTOS!M:M,"--",0,1) -> 6 | AE8: 2 | AF8: =_xlfn.XLOOKUP(C8,ESTACIONES!B:B,ESTACIONES!N:N,0,0,1) -> 2.3356473 | AG8: =_xlfn.XLOOKUP(A8,'L y W'!A:A,'L y W'!B:B,0,0,1) -> #N/A | AH8: =_xlfn.XLOOKUP(A8,'L y W'!A:A,'L y W'!C:C,0,0,1) -> #N/A
A9: 1019 | B9: 2015-09-17T10-31-25_Mw_5,0 | C9: C11O | D9: 2015 | E9: 9 | F9: 17 | G9: 10 | H9: 31 | I9: 25 | J9: -30.933 | K9: -71.459 | L9: 5 | M9: 51.1 | N9: -30.696472 | O9: -70.958889 | P9: 0 | Q9: 402 | R9: 3.22 | S9: -- | T9: -- | U9: -- | V9: -- | W9: -- | X9: -- | Y9: 54.568472 | Z9: 74.759134 | AA9: 74.759134 | AB9: ID_1019 | AC9: 6 | AD9: =_xlfn.XLOOKUP(B9,EVENTOS!B:B,EVENTOS!M:M,"--",0,1) -> 6 | AE9: 2 | AF9: =_xlfn.XLOOKUP(C9,ESTACIONES!B:B,ESTACIONES!N:N,0,0,1) -> 2.3463048 | AG9: =_xlfn.XLOOKUP(A9,'L y W'!A:A,'L y W'!B:B,0,0,1) -> #N/A | AH9: =_xlfn.XLOOKUP(A9,'L y W'!A:A,'L y W'!C:C,0,0,1) -> #N/A
A10: 102 | B10: 2014-03-16T21-16-29_Mw_6,7 | C10: T08A | D10: 2014 | E10: 3 | F10: 16 | G10: 21 | H10: 16 | I10: 29 | J10: -19.965 | K10: -70.814 | L10: 6.7 | M10: 20.6 | N10: -20.27016 | O10: -70.09414 | P10: 0 | Q10: 680 | R10: 14.35 | S10: 284 | T10: 26 | U10: 54 | V10: 144 | W10: 69 | X10: 106 | Y10: 82.508249 | Z10: 85.040997 | AA10: 70.450035 | AB10: ID_102 | AC10: 7 | AD10: =_xlfn.XLOOKUP(B10,EVENTOS!B:B,EVENTOS!M:M,"--",0,1) -> 3 | AE10: 1 | AF10: =_xlfn.XLOOKUP(C10,ESTACIONES!B:B,ESTACIONES!N:N,0,0,1) -> 1.8458396 | AG10: =_xlfn.XLOOKUP(A10,'L y W'!A:A,'L y W'!B:B,0,0,1) -> 26.351176 | AH10: =_xlfn.XLOOKUP(A10,'L y W'!A:A,'L y W'!C:C,0,0,1) -> 17.599487
A11: 1021 | B11: 2015-09-17T10-31-25_Mw_5,0 | C11: C23O | D11: 2015 | E11: 9 | F11: 17 | G11: 10 | H11: 31 | I11: 25 | J11: -30.933 | K11: -71.459 | L11: 5 | M11: 51.1 | N11: -31.783711 | O11: -70.969739 | P11: 458 | Q11: 751 | R11: 2.1 | S11: -- | T11: -- | U11: -- | V11: -- | W11: -- | X11: -- | Y11: 105.18436 | Z11: 117.14084 | AA11: 117.14084 | AB11: ID_1021 | AC11: 8 | AD11: =_xlfn.XLOOKUP(B11,EVENTOS!B:B,EVENTOS!M:M,"--",0,1) -> 6 | AE11: 2 | AF11: =_xlfn.XLOOKUP(C11,ESTACIONES!B:B,ESTACIONES!N:N,0,0,1) -> 4.6375108 | AG11: =_xlfn.XLOOKUP(A11,'L y W'!A:A,'L y W'!B:B,0,0,1) -> #N/A | AH11: =_xlfn.XLOOKUP(A11,'L y W'!A:A,'L y W'!C:C,0,0,1) -> #N/A
A12: 1022 | B12: 2015-09-17T10-31-25_Mw_5,0 | C12: C26O | D12: 2015 | E12: 9 | F12: 17 | G12: 10 | H12: 31 | I12: 25 | J12: -30.933 | K12: -71.459 | L12: 5 | M12: 51.1 | N12: -30.25898 | O12: -71.49046 | P12: 10 | Q12: 364 | R12: 1.87 | S12: -- | T12: -- | U12: -- | V12: -- | W12: -- | X12: -- | Y12: 74.784465 | Z12: 90.58117 | AA12: 90.58117 | AB12: ID_1022 | AC12: 9 | AD12: =_xlfn.XLOOKUP(B12,EVENTOS!B:B,EVENTOS!M:M,"--",0,1) -> 6 | AE12: 2 | AF12: =_xlfn.XLOOKUP(C12,ESTACIONES!B:B,ESTACIONES!N:N,0,0,1) -> 4.3052866 | AG12: =_xlfn.XLOOKUP(A12,'L y W'!A:A,'L y W'!B:B,0,0,1) -> #N/A | AH12: =_xlfn.XLOOKUP(A12,'L y W'!A:A,'L y W'!C:C,0,0,1) -> #N/A
A13: 1023 | B13: 2015-09-17T10-31-25_Mw_5,0 | C13: C32O | D13: 2015 | E13: 9 | F13: 17 | G13: 10 | H13: 31 | I13: 25 | J13: -30.933 | K13: -71.459 | L13: 5 | M13: 51.1 | N13: -30.854861 | O13: -70.707333 | P13: 903 | Q13: 578 | R13: 6.51 | S13: -- | T13: -- | U13: -- | V13: -- | W13: -- | X13: -- | Y13: 72.38685 | Z13: 89.130062 | AA13: 89.130062 | AB13: ID_1023 | AC13: 10 | AD13: =_xlfn.XLOOKUP(B13,EVENTOS!B:B,EVENTOS!M:M,"--",0,1) -> 6 | AE13: 2 | AF13: =_xlfn.XLOOKUP(C13,ESTACIONES!B:B,ESTACIONES!N:N,0,0,1) -> 2.2846909 | AG13: =_xlfn.XLOOKUP(A13,'L y W'!A:A,'L y W'!B:B,0,0,1) -> #N/A | AH13: =_xlfn.XLOOKUP(A13,'L y W'!A:A,'L y W'!C:C,0,0,1) -> #N/A
A14: 1025 | B14: 2015-09-17T12-58-8_Mw_4,9 | C14: C11O | D14: 2015 | E14: 9 | F14: 17 | G14: 12 | H14: 58 | I14: 8 | J14: -30.694 | K14: -71.559 | L14: 4.9 | M14: 31.9 | N14: -30.696472 | O14: -70.958889 | P14: 0 | Q14: 402 | R14: 3.22 | S14: -- | T14: -- | U14: -- | V14: -- | W14: -- | X14: -- | Y14: 57.495205 | Z14: 65.751871 | AA14: 65.751871 | AB14: ID_1025 | AC14: 6 | AD14: =_xlfn.XLOOKUP(B14,EVENTOS!B:B,EVENTOS!M:M,"--",0,1) -> 7 | AE14: 1 | AF14: =_xlfn.XLOOKUP(C14,ESTACIONES!B:B,ESTACIONES!N:N,0,0,1) -> 2.3463048 | AG14: =_xlfn.XLOOKUP(A14,'L y W'!A:A,'L y W'!B:B,0,0,1) -> #N/A | AH14: =_xlfn.XLOOKUP(A14,'L y W'!A:A,'L y W'!C:C,0,0,1) -> #N/A
A15: 1026 | B15: 2015-09-17T12-58-8_Mw_4,9 | C15: C26O | D15: 2015 | E15: 9 | F15: 17 | G15: 12 | H15: 58 | I15: 8 | J15: -30.694 | K15: -71.559 | L15: 4.9 | M15: 31.9 | N15: -30.25898 | O15: -71.49046 | P15: 10 | Q15: 364 | R15: 1.87 | S15: -- | T15: -- | U15: -- | V15: -- | W15: -- | X15: -- | Y15: 48.673535 | Z15: 58.20104 | AA15: 58.20104 | AB15: ID_1026 | AC15: 9 | AD15: =_xlfn.XLOOKUP(B15,EVENTOS!B:B,EVENTOS!M:M,"--",0,1) -> 7 | AE15: 1 | AF15: =_xlfn.XLOOKUP(C15,ESTACIONES!B:B,ESTACIONES!N:N,0,0,1) -> 4.3052866 | AG15: =_xlfn.XLOOKUP(A15,'L y W'!A:A,'L y W'!B:B,0,0,1) -> #N/A | AH15: =_xlfn.XLOOKUP(A15,'L y W'!A:A,'L y W'!C:C,0,0,1) -> #N/A
A16: 1027 | B16: 2015-09-17T13-32-26_Mw_6,0 | C16: C23O | D16: 2015 | E16: 9 | F16: 17 | G16: 13 | H16: 32 | I16: 26 | J16: -32.143 | K16: -72.173 | L16: 6 | M16: 33.6 | N16: -31.783711 | O16: -70.969739 | P16: 458 | Q16: 751 | R16: 2.1 | S16: 357 | T16: 22 | U16: 87 | V16: 181 | W16: 68 | X16: 91 | Y16: 120.51956 | Z16: 125.23942 | AA16: 120.38004 | AB16: ID_1027 | AC16: 8 | AD16: =_xlfn.XLOOKUP(B16,EVENTOS!B:B,EVENTOS!M:M,"--",0,1) -> 8 | AE16: 1 | AF16: =_xlfn.XLOOKUP(C16,ESTACIONES!B:B,ESTACIONES!N:N,0,0,1) -> 4.6375108 | AG16: =_xlfn.XLOOKUP(A16,'L y W'!A:A,'L y W'!B:B,0,0,1) -> 9.7948999 | AH16: =_xlfn.XLOOKUP(A16,'L y W'!A:A,'L y W'!C:C,0,0,1) -> 8.7297137
A17: 1028 | B17: 2015-09-17T13-32-26_Mw_6,0 | C17: R13M | D17: 2015 | E17: 9 | F17: 17 | G17: 13 | H17: 32 | I17: 26 | J17: -32.143 | K17: -72.173 | L17: 6 | M17: 33.6 | N17: -33.215583 | O17: -70.766861 | P17: 0 | Q17: 401 | R17: 1.31 | S17: 357 | T17: 22 | U17: 87 | V17: 181 | W17: 68 | X17: 91 | Y17: 177.5951 | Z17: 180.74562 | AA17: 175.42783 | AB17: ID_1028 | AC17: 11 | AD17: =_xlfn.XLOOKUP(B17,EVENTOS!B:B,EVENTOS!M:M,"--",0,1) -> 8 | AE17: 1 | AF17: =_xlfn.XLOOKUP(C17,ESTACIONES!B:B,ESTACIONES!N:N,0,0,1) -> 2.7481273 | AG17: =_xlfn.XLOOKUP(A17,'L y W'!A:A,'L y W'!B:B,0,0,1) -> 9.7948999 | AH17: =_xlfn.XLOOKUP(A17,'L y W'!A:A,'L y W'!C:C,0,0,1) -> 8.7297137
A18: 1029 | B18: 2015-09-17T13-32-26_Mw_6,0 | C18: V15A | D18: 2015 | E18: 9 | F18: 17 | G18: 13 | H18: 32 | I18: 26 | J18: -32.143 | K18: -72.173 | L18: 6 | M18: 33.6 | N18: -32.914889 | O18: -71.232592 | P18: 116 | Q18: 549 | R18: 5.72 | S18: 357 | T18: 22 | U18: 87 | V18: 181 | W18: 68 | X18: 91 | Y18: 123.01366 | Z18: 127.5505 | AA18: 122.13412 | AB18: ID_1029 | AC18: 12 | AD18: =_xlfn.XLOOKUP(B18,EVENTOS!B:B,EVENTOS!M:M,"--",0,1) -> 8 | AE18: 1 | AF18: =_xlfn.XLOOKUP(C18,ESTACIONES!B:B,ESTACIONES!N:N,0,0,1) -> 6.9467602 | AG18: =_xlfn.XLOOKUP(A18,'L y W'!A:A,'L y W'!B:B,0,0,1) -> 9.7948999 | AH18: =_xlfn.XLOOKUP(A18,'L y W'!A:A,'L y W'!C:C,0,0,1) -> 8.7297137
A19: 103 | B19: 2014-03-16T21-16-29_Mw_6,7 | C19: T09A | D19: 2014 | E19: 3 | F19: 16 | G19: 21 | H19: 16 | I19: 29 | J19: -19.965 | K19: -70.814 | L19: 6.7 | M19: 20.6 | N19: -19.59571 | O19: -70.21078 | P19: 0 | Q19: 826 | R19: 25 | S19: 284 | T19: 26 | U19: 54 | V19: 144 | W19: 69 | X19: 106 | Y19: 75.27966 | Z19: 78.04734 | AA19: 65.341026 | AB19: ID_103 | AC19: 13 | AD19: =_xlfn.XLOOKUP(B19,EVENTOS!B:B,EVENTOS!M:M,"--",0,1) -> 3 | AE19: 1 | AF19: =_xlfn.XLOOKUP(C19,ESTACIONES!B:B,ESTACIONES!N:N,0,0,1) -> 3.024097 | AG19: =_xlfn.XLOOKUP(A19,'L y W'!A:A,'L y W'!B:B,0,0,1) -> 26.351176 | AH19: =_xlfn.XLOOKUP(A19,'L y W'!A:A,'L y W'!C:C,0,0,1) -> 17.599487
A20: 1032 | B20: 2015-09-17T16-46-23_Mw_5,0 | C20: C11O | D20: 2015 | E20: 9 | F20: 17 | G20: 16 | H20: 46 | I20: 23 | J20: -31.504 | K20: -71.737 | L20: 5 | M20: 41.8 | N20: -30.696472 | O20: -70.958889 | P20: 0 | Q20: 402 | R20: 3.22 | S20: -- | T20: -- | U20: -- | V20: -- | W20: -- | X20: -- | Y20: 116.30365 | Z20: 123.58713 | AA20: 123.58713 | AB20: ID_1032 | AC20: 6 | AD20: =_xlfn.XLOOKUP(B20,EVENTOS!B:B,EVENTOS!M:M,"--",0,1) -> 9 | AE20: 1 | AF20: =_xlfn.XLOOKUP(C20,ESTACIONES!B:B,ESTACIONES!N:N,0,0,1) -> 2.3463048 | AG20: =_xlfn.XLOOKUP(A20,'L y W'!A:A,'L y W'!B:B,0,0,1) -> #N/A | AH20: =_xlfn.XLOOKUP(A20,'L y W'!A:A,'L y W'!C:C,0,0,1) -> #N/A
A21: 1033 | B21: 2015-09-17T16-46-23_Mw_5,0 | C21: C23O | D21: 2015 | E21: 9 | F21: 17 | G21: 16 | H21: 46 | I21: 23 | J21: -31.504 | K21: -71.737 | L21: 5 | M21: 41.8 | N21: -31.783711 | O21: -70.969739 | P21: 458 | Q21: 751 | R21: 2.1 | S21: -- | T21: -- | U21: -- | V21: -- | W21: -- | X21: -- | Y21: 79.112245 | Z21: 89.691058 | AA21: 89.691058 | AB21: ID_1033 | AC21: 8 | AD21: =_xlfn.XLOOKUP(B21,EVENTOS!B:B,EVENTOS!M:M,"--",0,1) -> 9 | AE21: 1 | AF21: =_xlfn.XLOOKUP(C21,ESTACIONES!B:B,ESTACIONES!N:N,0,0,1) -> 4.6375108 | AG21: =_xlfn.XLOOKUP(A21,'L y W'!A:A,'L y W'!B:B,0,0,1) -> #N/A | AH21: =_xlfn.XLOOKUP(A21,'L y W'!A:A,'L y W'!C:C,0,0,1) -> #N/A
A22: 1034 | B22: 2015-09-17T16-52-20_Mw_5,3 | C22: C26O | D22: 2015 | E22: 9 | F22: 17 | G22: 16 | H22: 52 | I22: 20 | J22: -29.935 | K22: -71.961 | L22: 5.3 | M22: 30 | N22: -30.25898 | O22: -71.49046 | P22: 10 | Q22: 364 | R22: 1.87 | S22: -- | T22: -- | U22: -- | V22: -- | W22: -- | X22: -- | Y22: 57.853647 | Z22: 65.173956 | AA22: 65.173956 | AB22: ID_1034 | AC22: 9 | AD22: =_xlfn.XLOOKUP(B22,EVENTOS!B:B,EVENTOS!M:M,"--",0,1) -> 10 | AE22: 1 | AF22: =_xlfn.XLOOKUP(C22,ESTACIONES!B:B,ESTACIONES!N:N,0,0,1) -> 4.3052866 | AG22: =_xlfn.XLOOKUP(A22,'L y W'!A:A,'L y W'!B:B,0,0,1) -> #N/A | AH22: =_xlfn.XLOOKUP(A22,'L y W'!A:A,'L y W'!C:C,0,0,1) -> #N/A
A23: 1035 | B23: 2015-09-17T16-8-9_Mw_5,3 | C23: C10O | D23: 2015 | E23: 9 | F23: 17 | G23: 16 | H23: 8 | I23: 9 | J23: -29.854 | K23: -70.485 | L23: 5.3 | M23: 39.2 | N23: -30.23387 | O23: -71.08159 | P23: 1032 | Q23: 517 | R23: 6.5 | S23: -- | T23: -- | U23: -- | V23: -- | W23: -- | X23: -- | Y23: 71.300443 | Z23: 81.867985 | AA23: 81.867985 | AB23: ID_1035 | AC23: 5 | AD23: =_xlfn.XLOOKUP(B23,EVENTOS!B:B,EVENTOS!M:M,"--",0,1) -> 11 | AE23: 1 | AF23: =_xlfn.XLOOKUP(C23,ESTACIONES!B:B,ESTACIONES!N:N,0,0,1) -> 2.3356473 | AG23: =_xlfn.XLOOKUP(A23,'L y W'!A:A,'L y W'!B:B,0,0,1) -> #N/A | AH23: =_xlfn.XLOOKUP(A23,'L y W'!A:A,'L y W'!C:C,0,0,1) -> #N/A
A24: 1038 | B24: 2015-09-17T16-8-9_Mw_5,3 | C24: C23O | D24: 2015 | E24: 9 | F24: 17 | G24: 16 | H24: 8 | I24: 9 | J24: -29.854 | K24: -70.485 | L24: 5.3 | M24: 39.2 | N24: -31.783711 | O24: -70.969739 | P24: 458 | Q24: 751 | R24: 2.1 | S24: -- | T24: -- | U24: -- | V24: -- | W24: -- | X24: -- | Y24: 218.9092 | Z24: 222.47245 | AA24: 222.47245 | AB24: ID_1038 | AC24: 8 | AD24: =_xlfn.XLOOKUP(B24,EVENTOS!B:B,EVENTOS!M:M,"--",0,1) -> 11 | AE24: 1 | AF24: =_xlfn.XLOOKUP(C24,ESTACIONES!B:B,ESTACIONES!N:N,0,0,1) -> 4.6375108 | AG24: =_xlfn.XLOOKUP(A24,'L y W'!A:A,'L y W'!B:B,0,0,1) -> #N/A | AH24: =_xlfn.XLOOKUP(A24,'L y W'!A:A,'L y W'!C:C,0,0,1) -> #N/A
A25: 104 | B25: 2014-03-16T21-16-29_Mw_6,7 | C25: T13A | D25: 2014 | E25: 3 | F25: 16 | G25: 21 | H25: 16 | I25: 29 | J25: -19.965 | K25: -70.814 | L25: 6.7 | M25: 20.6 | N25: -20.496328 | O25: -69.33747 | P25: 0 | Q25: 357 | R25: 2.08 | S25: 284 | T25: 26 | U25: 54 | V25: 144 | W25: 69 | X25: 106 | Y25: 165.11957 | Z25: 166.39962 | AA25: 152.39635 | AB25: ID_104 | AC25: 14 | AD25: =_xlfn.XLOOKUP(B25,EVENTOS!B:B,EVENTOS!M:M,"--",0,1) -> 3 | AE25: 1 | AF25: =_xlfn.XLOOKUP(C25,ESTACIONES!B:B,ESTACIONES!N:N,0,0,1) -> 2.8487109 | AG25: =_xlfn.XLOOKUP(A25,'L y W'!A:A,'L y W'!B:B,0,0,1) -> 26.351176 | AH25: =_xlfn.XLOOKUP(A25,'L y W'!A:A,'L y W'!C:C,0,0,1) -> 17.599487
A26: 1040 | B26: 2015-09-17T17-32-20_Mw_4,8 | C26: C11O | D26: 2015 | E26: 9 | F26: 17 | G26: 17 | H26: 32 | I26: 20 | J26: -30.684 | K26: -71.614 | L26: 4.8 | M26: 33.3 | N26: -30.696472 | O26: -70.958889 | P26: 0 | Q26: 402 | R26: 3.22 | S26: -- | T26: -- | U26: -- | V26: -- | W26: -- | X26: -- | Y26: 62.782359 | Z26: 71.066973 | AA26: 71.066973 | AB26: ID_1040 | AC26: 6 | AD26: =_xlfn.XLOOKUP(B26,EVENTOS!B:B,EVENTOS!M:M,"--",0,1) -> 12 | AE26: 1 | AF26: =_xlfn.XLOOKUP(C26,ESTACIONES!B:B,ESTACIONES!N:N,0,0,1) -> 2.3463048 | AG26: =_xlfn.XLOOKUP(A26,'L y W'!A:A,'L y W'!B:B,0,0,1) -> #N/A | AH26: =_xlfn.XLOOKUP(A26,'L y W'!A:A,'L y W'!C:C,0,0,1) -> #N/A
A27: 1043 | B27: 2015-09-17T2-44-26_Mw_4,8 | C27: C23O | D27: 2015 | E27: 9 | F27: 17 | G27: 2 | H27: 44 | I27: 26 | J27: -31.239 | K27: -71.773 | L27: 4.8 | M27: 33.3 | N27: -31.783711 | O27: -70.969739 | P27: 458 | Q27: 751 | R27: 2.1 | S27: -- | T27: -- | U27: -- | V27: -- | W27: -- | X27: -- | Y27: 97.312358 | Z27: 103.00144 | AA27: 103.00144 | AB27: ID_1043 | AC27: 8 | AD27: =_xlfn.XLOOKUP(B27,EVENTOS!B:B,EVENTOS!M:M,"--",0,1) -> 13 | AE27: 1 | AF27: =_xlfn.XLOOKUP(C27,ESTACIONES!B:B,ESTACIONES!N:N,0,0,1) -> 4.6375108 | AG27: =_xlfn.XLOOKUP(A27,'L y W'!A:A,'L y W'!B:B,0,0,1) -> #N/A | AH27: =_xlfn.XLOOKUP(A27,'L y W'!A:A,'L y W'!C:C,0,0,1) -> #N/A
A28: 1044 | B28: 2015-09-17T2-52-43_Mw_4,8 | C28: C11O | D28: 2015 | E28: 9 | F28: 17 | G28: 2 | H28: 52 | I28: 43 | J28: -30.92 | K28: -71.35 | L28: 4.8 | M28: 44.7 | N28: -30.696472 | O28: -70.958889 | P28: 0 | Q28: 402 | R28: 3.22 | S28: -- | T28: -- | U28: -- | V28: -- | W28: -- | X28: -- | Y28: 44.887977 | Z28: 63.348405 | AA28: 63.348405 | AB28: ID_1044 | AC28: 6 | AD28: =_xlfn.XLOOKUP(B28,EVENTOS!B:B,EVENTOS!M:M,"--",0,1) -> 14 | AE28: 1 | AF28: =_xlfn.XLOOKUP(C28,ESTACIONES!B:B,ESTACIONES!N:N,0,0,1) -> 2.3463048 | AG28: =_xlfn.XLOOKUP(A28,'L y W'!A:A,'L y W'!B:B,0,0,1) -> #N/A | AH28: =_xlfn.XLOOKUP(A28,'L y W'!A:A,'L y W'!C:C,0,0,1) -> #N/A
A29: 1046 | B29: 2015-09-17T2-59-28_Mw_5,5 | C29: C10O | D29: 2015 | E29: 9 | F29: 17 | G29: 2 | H29: 59 | I29: 28 | J29: -30.98 | K29: -71.364 | L29: 5.5 | M29: 53.7 | N29: -30.23387 | O29: -71.08159 | P29: 1032 | Q29: 517 | R29: 6.5 | S29: -- | T29: -- | U29: -- | V29: -- | W29: -- | X29: -- | Y29: 87.038201 | Z29: 102.81654 | AA29: 102.81654 | AB29: ID_1046 | AC29: 5 | AD29: =_xlfn.XLOOKUP(B29,EVENTOS!B:B,EVENTOS!M:M,"--",0,1) -> 15 | AE29: 2 | AF29: =_xlfn.XLOOKUP(C29,ESTACIONES!B:B,ESTACIONES!N:N,0,0,1) -> 2.3356473 | AG29: =_xlfn.XLOOKUP(A29,'L y W'!A:A,'L y W'!B:B,0,0,1) -> #N/A | AH29: =_xlfn.XLOOKUP(A29,'L y W'!A:A,'L y W'!C:C,0,0,1) -> #N/A
A30: 1047 | B30: 2015-09-17T2-59-28_Mw_5,5 | C30: C11O | D30: 2015 | E30: 9 | F30: 17 | G30: 2 | H30: 59 | I30: 28 | J30: -30.98 | K30: -71.364 | L30: 5.5 | M30: 53.7 | N30: -30.696472 | O30: -70.958889 | P30: 0 | Q30: 402 | R30: 3.22 | S30: -- | T30: -- | U30: -- | V30: -- | W30: -- | X30: -- | Y30: 49.900153 | Z30: 73.305629 | AA30: 73.305629 | AB30: ID_1047 | AC30: 6 | AD30: =_xlfn.XLOOKUP(B30,EVENTOS!B:B,EVENTOS!M:M,"--",0,1) -> 15 | AE30: 2 | AF30: =_xlfn.XLOOKUP(C30,ESTACIONES!B:B,ESTACIONES!N:N,0,0,1) -> 2.3463048 | AG30: =_xlfn.XLOOKUP(A30,'L y W'!A:A,'L y W'!B:B,0,0,1) -> #N/A | AH30: =_xlfn.XLOOKUP(A30,'L y W'!A:A,'L y W'!C:C,0,0,1) -> #N/A
A31: 105 | B31: 2014-03-17T11-12-17_Mw_5,1 | C31: T07A | D31: 2014 | E31: 3 | F31: 17 | G31: 11 | H31: 12 | I31: 17 | J31: -19.912 | K31: -70.908 | L31: 5.1 | M31: 32.9 | N31: -20.25627 | O31: -69.78601 | P31: 0 | Q31: 344 | R31: 2.47 | S31: 348 | T31: 25 | U31: 89 | V31: 169 | W31: 65 | X31: 90 | Y31: 123.38391 | Z31: 127.69495 | AA31: 133.71 | AB31: ID_105 | AC31: 15 | AD31: =_xlfn.XLOOKUP(B31,EVENTOS!B:B,EVENTOS!M:M,"--",0,1) -> 16 | AE31: 1 | AF31: =_xlfn.XLOOKUP(C31,ESTACIONES!B:B,ESTACIONES!N:N,0,0,1) -> 4.7744006 | AG31: =_xlfn.XLOOKUP(A31,'L y W'!A:A,'L y W'!B:B,0,0,1) -> 0 | AH31: =_xlfn.XLOOKUP(A31,'L y W'!A:A,'L y W'!C:C,0,0,1) -> 0
A32: 1051 | B32: 2015-09-17T2-59-28_Mw_5,5 | C32: C26O | D32: 2015 | E32: 9 | F32: 17 | G32: 2 | H32: 59 | I32: 28 | J32: -30.98 | K32: -71.364 | L32: 5.5 | M32: 53.7 | N32: -30.25898 | O32: -71.49046 | P32: 10 | Q32: 364 | R32: 1.87 | S32: -- | T32: -- | U32: -- | V32: -- | W32: -- | X32: -- | Y32: 80.848779 | Z32: 97.063326 | AA32: 97.063326 | AB32: ID_1051 | AC32: 9 | AD32: =_xlfn.XLOOKUP(B32,EVENTOS!B:B,EVENTOS!M:M,"--",0,1) -> 15 | AE32: 2 | AF32: =_xlfn.XLOOKUP(C32,ESTACIONES!B:B,ESTACIONES!N:N,0,0,1) -> 4.3052866 | AG32: =_xlfn.XLOOKUP(A32,'L y W'!A:A,'L y W'!B:B,0,0,1) -> #N/A | AH32: =_xlfn.XLOOKUP(A32,'L y W'!A:A,'L y W'!C:C,0,0,1) -> #N/A
A33: 1052 | B33: 2015-09-17T2-59-28_Mw_5,5 | C33: C32O | D33: 2015 | E33: 9 | F33: 17 | G33: 2 | H33: 59 | I33: 28 | J33: -30.98 | K33: -71.364 | L33: 5.5 | M33: 53.7 | N33: -30.854861 | O33: -70.707333 | P33: 903 | Q33: 578 | R33: 6.51 | S33: -- | T33: -- | U33: -- | V33: -- | W33: -- | X33: -- | Y33: 64.28337 | Z33: 84.343579 | AA33: 84.343579 | AB33: ID_1052 | AC33: 10 | AD33: =_xlfn.XLOOKUP(B33,EVENTOS!B:B,EVENTOS!M:M,"--",0,1) -> 15 | AE33: 2 | AF33: =_xlfn.XLOOKUP(C33,ESTACIONES!B:B,ESTACIONES!N:N,0,0,1) -> 2.2846909 | AG33: =_xlfn.XLOOKUP(A33,'L y W'!A:A,'L y W'!B:B,0,0,1) -> #N/A | AH33: =_xlfn.XLOOKUP(A33,'L y W'!A:A,'L y W'!C:C,0,0,1) -> #N/A
A34: 1053 | B34: 2015-09-17T20-40-34_Mw_5,5 | C34: C01O | D34: 2015 | E34: 9 | F34: 17 | G34: 20 | H34: 40 | I34: 34 | J34: -30.036 | K34: -71.671 | L34: 5.5 | M34: 32.7 | N34: -29.87719 | O34: -71.23787 | P34: 0 | Q34: 399 | R34: 1.18 | S34: 357 | T34: 30 | U34: 103 | V34: 162 | W34: 61 | X34: 82 | Y34: 45.364357 | Z34: 55.921506 | AA34: 55.897449 | AB34: ID_1053 | AC34: 16 | AD34: =_xlfn.XLOOKUP(B34,EVENTOS!B:B,EVENTOS!M:M,"--",0,1) -> 17 | AE34: 1 | AF34: =_xlfn.XLOOKUP(C34,ESTACIONES!B:B,ESTACIONES!N:N,0,0,1) -> 2.8226613 | AG34: =_xlfn.XLOOKUP(A34,'L y W'!A:A,'L y W'!B:B,0,0,1) -> 0 | AH34: =_xlfn.XLOOKUP(A34,'L y W'!A:A,'L y W'!C:C,0,0,1) -> 0
A35: 1054 | B35: 2015-09-17T20-40-34_Mw_5,5 | C35: C10O | D35: 2015 | E35: 9 | F35: 17 | G35: 20 | H35: 40 | I35: 34 | J35: -30.036 | K35: -71.671 | L35: 5.5 | M35: 32.7 | N35: -30.23387 | O35: -71.08159 | P35: 1032 | Q35: 517 | R35: 6.5 | S35: 357 | T35: 30 | U35: 103 | V35: 162 | W35: 61 | X35: 82 | Y35: 60.881479 | Z35: 69.601741 | AA35: 69.155167 | AB35: ID_1054 | AC35: 5 | AD35: =_xlfn.XLOOKUP(B35,EVENTOS!B:B,EVENTOS!M:M,"--",0,1) -> 17 | AE35: 1 | AF35: =_xlfn.XLOOKUP(C35,ESTACIONES!B:B,ESTACIONES!N:N,0,0,1) -> 2.3356473 | AG35: =_xlfn.XLOOKUP(A35,'L y W'!A:A,'L y W'!B:B,0,0,1) -> 0 | AH35: =_xlfn.XLOOKUP(A35,'L y W'!A:A,'L y W'!C:C,0,0,1) -> 0
A36: 1055 | B36: 2015-09-17T20-40-34_Mw_5,5 | C36: C11O | D36: 2015 | E36: 9 | F36: 17 | G36: 20 | H36: 40 | I36: 34 | J36: -30.036 | K36: -71.671 | L36: 5.5 | M36: 32.7 | N36: -30.696472 | O36: -70.958889 | P36: 0 | Q36: 402 | R36: 3.22 | S36: 357 | T36: 30 | U36: 103 | V36: 162 | W36: 61 | X36: 82 | Y36: 100.23486 | Z36: 105.43394 | AA36: 105.58099 | AB36: ID_1055 | AC36: 6 | AD36: =_xlfn.XLOOKUP(B36,EVENTOS!B:B,EVENTOS!M:M,"--",0,1) -> 17 | AE36: 1 | AF36: =_xlfn.XLOOKUP(C36,ESTACIONES!B:B,ESTACIONES!N:N,0,0,1) -> 2.3463048 | AG36: =_xlfn.XLOOKUP(A36,'L y W'!A:A,'L y W'!B:B,0,0,1) -> 0 | AH36: =_xlfn.XLOOKUP(A36,'L y W'!A:A,'L y W'!C:C,0,0,1) -> 0
A37: 1058 | B37: 2015-09-17T20-40-34_Mw_5,5 | C37: C20O | D37: 2015 | E37: 9 | F37: 17 | G37: 20 | H37: 40 | I37: 34 | J37: -30.036 | K37: -71.671 | L37: 5.5 | M37: 32.7 | N37: -29.96818 | O37: -71.33736 | P37: 52 | Q37: 1106 | R37: 1.24 | S37: 357 | T37: 30 | U37: 103 | V37: 162 | W37: 61 | X37: 82 | Y37: 33.057232 | Z37: 46.534655 | AA37: 46.49123 | AB37: ID_1058 | AC37: 17 | AD37: =_xlfn.XLOOKUP(B37,EVENTOS!B:B,EVENTOS!M:M,"--",0,1) -> 17 | AE37: 1 | AF37: =_xlfn.XLOOKUP(C37,ESTACIONES!B:B,ESTACIONES!N:N,0,0,1) -> 4.0819377 | AG37: =_xlfn.XLOOKUP(A37,'L y W'!A:A,'L y W'!B:B,0,0,1) -> 0 | AH37: =_xlfn.XLOOKUP(A37,'L y W'!A:A,'L y W'!C:C,0,0,1) -> 0
A38: 1059 | B38: 2015-09-17T20-40-34_Mw_5,5 | C38: C22O | D38: 2015 | E38: 9 | F38: 17 | G38: 20 | H38: 40 | I38: 34 | J38: -30.036 | K38: -71.671 | L38: 5.5 | M38: 32.7 | N38: -29.96551 | O38: -71.35111 | P38: 36 | Q38: 1228 | R38: 6.4838235 | S38: 357 | T38: 30 | U38: 103 | V38: 162 | W38: 61 | X38: 82 | Y38: 31.838517 | Z38: 45.665488 | AA38: 45.632629 | AB38: ID_1059 | AC38: 18 | AD38: =_xlfn.XLOOKUP(B38,EVENTOS!B:B,EVENTOS!M:M,"--",0,1) -> 17 | AE38: 1 | AF38: =_xlfn.XLOOKUP(C38,ESTACIONES!B:B,ESTACIONES!N:N,0,0,1) -> 1.6562574 | AG38: =_xlfn.XLOOKUP(A38,'L y W'!A:A,'L y W'!B:B,0,0,1) -> 0 | AH38: =_xlfn.XLOOKUP(A38,'L y W'!A:A,'L y W'!C:C,0,0,1) -> 0
A39: 1060 | B39: 2015-09-17T20-40-34_Mw_5,5 | C39: C26O | D39: 2015 | E39: 9 | F39: 17 | G39: 20 | H39: 40 | I39: 34 | J39: -30.036 | K39: -71.671 | L39: 5.5 | M39: 32.7 | N39: -30.25898 | O39: -71.49046 | P39: 10 | Q39: 364 | R39: 1.87 | S39: 357 | T39: 30 | U39: 103 | V39: 162 | W39: 61 | X39: 82 | Y39: 30.224906 | Z39: 44.536379 | AA39: 44.536133 | AB39: ID_1060 | AC39: 9 | AD39: =_xlfn.XLOOKUP(B39,EVENTOS!B:B,EVENTOS!M:M,"--",0,1) -> 17 | AE39: 1 | AF39: =_xlfn.XLOOKUP(C39,ESTACIONES!B:B,ESTACIONES!N:N,0,0,1) -> 4.3052866 | AG39: =_xlfn.XLOOKUP(A39,'L y W'!A:A,'L y W'!B:B,0,0,1) -> 0 | AH39: =_xlfn.XLOOKUP(A39,'L y W'!A:A,'L y W'!C:C,0,0,1) -> 0
A40: 1063 | B40: 2015-09-17T20-40-34_Mw_5,5 | C40: GO04 | D40: 2015 | E40: 9 | F40: 17 | G40: 20 | H40: 40 | I40: 34 | J40: -30.036 | K40: -71.671 | L40: 5.5 | M40: 32.7 | N40: -30.1727 | O40: -70.7993 | P40: 0 | Q40: 405 | R40: 1.64 | S40: 357 | T40: 30 | U40: 103 | V40: 162 | W40: 61 | X40: 82 | Y40: 85.374358 | Z40: 91.422486 | AA40: 91.477829 | AB40: ID_1063 | AC40: 1 | AD40: =_xlfn.XLOOKUP(B40,EVENTOS!B:B,EVENTOS!M:M,"--",0,1) -> 17 | AE40: 1 | AF40: =_xlfn.XLOOKUP(C40,ESTACIONES!B:B,ESTACIONES!N:N,0,0,1) -> 5.4872095 | AG40: =_xlfn.XLOOKUP(A40,'L y W'!A:A,'L y W'!B:B,0,0,1) -> 0 | AH40: =_xlfn.XLOOKUP(A40,'L y W'!A:A,'L y W'!C:C,0,0,1) -> 0
...

Sheet EVENTOS
A1: ID Ev | B1: Event | C1: Year | D1: Month | E1: Day | F1: Hour | G1: Min | H1: Seg | I1: Lat Ev [°] | J1: Long Ev [°] | K1: Mag | L1: Depth [km] | M1: id_ev_num
A2: ="EV_"&M2 -> EV_1 | B2: 2012-03-03T11-1-47_Mw_5,6 | C2: 2012 | D2: 3 | E2: 3 | F2: 11 | G2: 1 | H2: 47 | I2: -30.189 | J2: -71.448 | K2: 5.6 | L2: 34.6 | M2: 1
A3: ="EV_"&M3 -> EV_2 | B3: 2012-04-01T7-31-36_Mw_5,2 | C3: 2012 | D3: 4 | E3: 1 | F3: 7 | G3: 31 | H3: 36 | I3: -23.056 | J3: -69.316 | K3: 5.2 | L3: 93.8 | M3: 2
A4: ="EV_"&M4 -> EV_3 | B4: 2014-03-16T21-16-29_Mw_6,7 | C4: 2014 | D4: 3 | E4: 16 | F4: 21 | G4: 16 | H4: 29 | I4: -19.965 | J4: -70.814 | K4: 6.7 | L4: 20.6 | M4: 3
A5: ="EV_"&M5 -> EV_4 | B5: 2015-09-17T1-41-5_Mw_6,5 | C5: 2015 | D5: 9 | E5: 17 | F5: 1 | G5: 41 | H5: 5 | I5: -31.113 | J5: -71.651 | K5: 6.5 | L5: 49.5 | M5: 4
A6: ="EV_"&M6 -> EV_5 | B6: 2015-09-17T10-12-53_Mw_5,3 | C6: 2015 | D6: 9 | E6: 17 | F6: 10 | G6: 12 | H6: 53 | I6: -30.536 | J6: -71.632 | K6: 5.3 | L6: 29.7 | M6: 5
A7: ="EV_"&M7 -> EV_6 | B7: 2015-09-17T10-31-25_Mw_5,0 | C7: 2015 | D7: 9 | E7: 17 | F7: 10 | G7: 31 | H7: 25 | I7: -30.933 | J7: -71.459 | K7: 5 | L7: 51.1 | M7: 6
A8: ="EV_"&M8 -> EV_7 | B8: 2015-09-17T12-58-8_Mw_4,9 | C8: 2015 | D8: 9 | E8: 17 | F8: 12 | G8: 58 | H8: 8 | I8: -30.694 | J8: -71.559 | K8: 4.9 | L8: 31.9 | M8: 7
A9: ="EV_"&M9 -> EV_8 | B9: 2015-09-17T13-32-26_Mw_6,0 | C9: 2015 | D9: 9 | E9: 17 | F9: 13 | G9: 32 | H9: 26 | I9: -32.143 | J9: -72.173 | K9: 6 | L9: 33.6 | M9: 8
A10: ="EV_"&M10 -> EV_9 | B10: 2015-09-17T16-46-23_Mw_5,0 | C10: 2015 | D10: 9 | E10: 17 | F10: 16 | G10: 46 | H10: 23 | I10: -31.504 | J10: -71.737 | K10: 5 | L10: 41.8 | M10: 9
A11: ="EV_"&M11 -> EV_10 | B11: 2015-09-17T16-52-20_Mw_5,3 | C11: 2015 | D11: 9 | E11: 17 | F11: 16 | G11: 52 | H11: 20 | I11: -29.935 | J11: -71.961 | K11: 5.3 | L11: 30 | M11: 10
A12: ="EV_"&M12 -> EV_11 | B12: 2015-09-17T16-8-9_Mw_5,3 | C12: 2015 | D12: 9 | E12: 17 | F12: 16 | G12: 8 | H12: 9 | I12: -29.854 | J12: -70.485 | K12: 5.3 | L12: 39.2 | M12: 11
A13: ="EV_"&M13 -> EV_12 | B13: 2015-09-17T17-32-20_Mw_4,8 | C13: 2015 | D13: 9 | E13: 17 | F13: 17 | G13: 32 | H13: 20 | I13: -30.684 | J13: -71.614 | K13: 4.8 | L13: 33.3 | M13: 12
... A789: ="EV_"&M789 -> EV_788 | B789: 2015-09-17T0-6-18_Mw_5,3 | C789: 2015 | D789: 9 | E789: 17 | F789: 0 | G789: 6 | H789: 18 | I789: -30.996 | J789: -71.478 | K789: 5.3 | L789: 38.4 | M789: 788

Sheet ESTACIONES
A1: ID Est | B1: Est | C1: Lat Est [°] | D1: Long Est [°] | E1: Elevación [m] | F1: Vs30 [m/s] | G1: F0 [Hz] | H1: F0 calc | I1: F0 def | J1: id_n_est | K1: k_0 | L1: k_R | M1: kappa | N1: A0
A2: EST_1 | B2: GO04 | C2: -30.1727 | D2: -70.7993 | E2: 0 | F2: 405 | G2: 1.64 | H2: -- | I2: 1.64 | J2: =1 -> 1 | K2: =(_xlfn.XLOOKUP(B2,Hoja1!A:A,Hoja1!G:G,"--",0,1)) -> 0.048 | L2: =_xlfn.XLOOKUP(B2,Hoja1!A:A,Hoja1!H:H,"--",0,1) -> 8.616e-05 | M2: =IF(K2="--",POWER(10,-0.2233*LOG10(I2)-2.901),"--") -> -- | N2: =_xlfn.XLOOKUP(B2,f0_a0!A:A,f0_a0!C:C,0,0,1) -> 5.4872095
A3: EST_2 | B3: PB06 | C3: -22.7058 | D3: -69.57188 | E3: 0 | F3: 736 | G3: 7.94 | H3: -- | I3: 7.94 | J3: =J2+1 -> 2 | K3: =(_xlfn.XLOOKUP(B3,Hoja1!A:A,Hoja1!G:G,"--",0,1)) -> 0.006 | L3: =_xlfn.XLOOKUP(B3,Hoja1!A:A,Hoja1!H:H,"--",0,1) -> 0.00014789 | M3: =IF(K3="--",POWER(10,-0.2233*LOG10(I3)-2.901),"--") -> -- | N3: =_xlfn.XLOOKUP(B3,f0_a0!A:A,f0_a0!C:C,0,0,1) -> 1.793958
A4: EST_3 | B4: T03A | C4: -20.23034 | D4: -70.14592 | E4: 0 | F4: 635 | G4: 7.01 | H4: -- | I4: 7.01 | J4: =J3+1 -> 3 | K4: =(_xlfn.XLOOKUP(B4,Hoja1!A:A,Hoja1!G:G,"--",0,1)) -> -- | L4: =_xlfn.XLOOKUP(B4,Hoja1!A:A,Hoja1!H:H,"--",0,1) -> -- | M4: =IF(K4="--",POWER(10,-0.2233*LOG10(I4)-2.901),"--") -> 0.00081311349 | N4: =_xlfn.XLOOKUP(B4,f0_a0!A:A,f0_a0!C:C,0,0,1) -> 6.1460543
A5: EST_4 | B5: T06A | C5: -20.2142 | D5: -70.13789 | E5: 0 | F5: 276 | G5: 1.67 | H5: -- | I5: 1.67 | J5: =J4+1 -> 4 | K5: =(_xlfn.XLOOKUP(B5,Hoja1!A:A,Hoja1!G:G,"--",0,1)) -> -- | L5: =_xlfn.XLOOKUP(B5,Hoja1!A:A,Hoja1!H:H,"--",0,1) -> -- | M5: =IF(K5="--",POWER(10,-0.2233*LOG10(I5)-2.901),"--") -> 0.0011201274 | N5: =_xlfn.XLOOKUP(B5,f0_a0!A:A,f0_a0!C:C,0,0,1) -> 1.8913069
A6: EST_5 | B6: C10O | C6: -30.23387 | D6: -71.08159 | E6: 1032 | F6: 517 | G6: 6.5 | H6: -- | I6: 6.5 | J6: =J5+1 -> 5 | K6: =(_xlfn.XLOOKUP(B6,Hoja1!A:A,Hoja1!G:G,"--",0,1)) -> -- | L6: =_xlfn.XLOOKUP(B6,Hoja1!A:A,Hoja1!H:H,"--",0,1) -> -- | M6: =IF(K6="--",POWER(10,-0.2233*LOG10(I6)-2.901),"--") -> 0.00082694466 | N6: =_xlfn.XLOOKUP(B6,f0_a0!A:A,f0_a0!C:C,0,0,1) -> 2.3356473
A7: EST_6 | B7: C11O | C7: -30.696472 | D7: -70.958889 | E7: 0 | F7: 402 | G7: 3.22 | H7: -- | I7: 3.22 | J7: =J6+1 -> 6 | K7: =(_xlfn.XLOOKUP(B7,Hoja1!A:A,Hoja1!G:G,"--",0,1)) -> -- | L7: =_xlfn.XLOOKUP(B7,Hoja1!A:A,Hoja1!H:H,"--",0,1) -> -- | M7: =IF(K7="--",POWER(10,-0.2233*LOG10(I7)-2.901),"--") -> 0.00096737706 | N7: =_xlfn.XLOOKUP(B7,f0_a0!A:A,f0_a0!C:C,0,0,1) -> 2.3463048
A8: EST_7 | B8: T08A | C8: -20.27016 | D8: -70.09414 | E8: 0 | F8: 680 | G8: 14.35 | H8: -- | I8: 14.35 | J8: =J7+1 -> 7 | K8: =(_xlfn.XLOOKUP(B8,Hoja1!A:A,Hoja1!G:G,"--",0,1)) -> -- | L8: =_xlfn.XLOOKUP(B8,Hoja1!A:A,Hoja1!H:H,"--",0,1) -> -- | M8: =IF(K8="--",POWER(10,-0.2233*LOG10(I8)-2.901),"--") -> 0.00069290703 | N8: =_xlfn.XLOOKUP(B8,f0_a0!A:A,f0_a0!C:C,0,0,1) -> 1.8458396
A9: EST_8 | B9: C23O | C9: -31.783711 | D9: -70.969739 | E9: 458 | F9: 751 | G9: 2.1 | H9: -- | I9: 2.1 | J9: =J8+1 -> 8 | K9: =(_xlfn.XLOOKUP(B9,Hoja1!A:A,Hoja1!G:G,"--",0,1)) -> -- | L9: =_xlfn.XLOOKUP(B9,Hoja1!A:A,Hoja1!H:H,"--",0,1) -> -- | M9: =IF(K9="--",POWER(10,-0.2233*LOG10(I9)-2.901),"--") -> 0.0010642617 | N9: =_xlfn.XLOOKUP(B9,f0_a0!A:A,f0_a0!C:C,0,0,1) -> 4.6375108
A10: EST_9 | B10: C26O | C10: -30.25898 | D10: -71.49046 | E10: 10 | F10: 364 | G10: 1.87 | H10: -- | I10: 1.87 | J10: =J9+1 -> 9 | K10: =(_xlfn.XLOOKUP(B10,Hoja1!A:A,Hoja1!G:G,"--",0,1)) -> -- | L10: =_xlfn.XLOOKUP(B10,Hoja1!A:A,Hoja1!H:H,"--",0,1) -> -- | M10: =IF(K10="--",POWER(10,-0.2233*LOG10(I10)-2.901),"--") -> 0.0010921889 | N10: =_xlfn.XLOOKUP(B10,f0_a0!A:A,f0_a0!C:C,0,0,1) -> 4.3052866
A11: EST_10 | B11: C32O | C11: -30.854861 | D11: -70.707333 | E11: 903 | F11: 578 | G11: 6.51 | H11: -- | I11: 6.51 | J11: =J10+1 -> 10 | K11: =(_xlfn.XLOOKUP(B11,Hoja1!A:A,Hoja1!G:G,"--",0,1)) -> -- | L11: =_xlfn.XLOOKUP(B11,Hoja1!A:A,Hoja1!H:H,"--",0,1) -> -- | M11: =IF(K11="--",POWER(10,-0.2233*LOG10(I11)-2.901),"--") -> 0.00082666084 | N11: =_xlfn.XLOOKUP(B11,f0_a0!A:A,f0_a0!C:C,0,0,1) -> 2.2846909
A12: EST_11 | B12: R13M | C12: -33.215583 | D12: -70.766861 | E12: 0 | F12: 401 | G12: 1.31 | H12: -- | I12: 1.31 | J12: =J11+1 -> 11 | K12: =(_xlfn.XLOOKUP(B12,Hoja1!A:A,Hoja1!G:G,"--",0,1)) -> -- | L12: =_xlfn.XLOOKUP(B12,Hoja1!A:A,Hoja1!H:H,"--",0,1) -> -- | M12: =IF(K12="--",POWER(10,-0.2233*LOG10(I12)-2.901),"--") -> 0.0011825331 | N12: =_xlfn.XLOOKUP(B12,f0_a0!A:A,f0_a0!C:C,0,0,1) -> 2.7481273
A13: EST_12 | B13: V15A | C13: -32.914889 | D13: -71.232592 | E13: 116 | F13: 549 | G13: 5.72 | H13: -- | I13: 5.72 | J13: =J12+1 -> 12 | K13: =(_xlfn.XLOOKUP(B13,Hoja1!A:A,Hoja1!G:G,"--",0,1)) -> -- | L13: =_xlfn.XLOOKUP(B13,Hoja1!A:A,Hoja1!H:H,"--",0,1) -> -- | M13: =IF(K13="--",POWER(10,-0.2233*LOG10(I13)-2.901),"--") -> 0.00085089009 | N13: =_xlfn.XLOOKUP(B13,f0_a0!A:A,f0_a0!C:C,0,0,1) -> 6.9467602
A14: EST_13 | B14: T09A | C14: -19.59571 | D14: -70.21078 | E14: 0 | F14: 826 | G14: 25 | H14: -- | I14: 25 | J14: =J13+1 -> 13 | K14: =(_xlfn.XLOOKUP(B14,Hoja1!A:A,Hoja1!G:G,"--",0,1)) -> 0.012 | L14: =_xlfn.XLOOKUP(B14,Hoja1!A:A,Hoja1!H:H,"--",0,1) -> 0.00014141 | M14: =IF(K14="--",POWER(10,-0.2233*LOG10(I14)-2.901),"--") -> -- | N14: =_xlfn.XLOOKUP(B14,f0_a0!A:A,f0_a0!C:C,0,0,1) -> 3.024097
... A18: EST_17 | B18: C20O | C18: -29.96818 | D18: -71.33736 | E18: 52 | F18: 1106 | G18: 1.24 | H18: -- | I18: 1.24 | J18: =J17+1 -> 17 | K18: =(_xlfn.XLOOKUP(B18,Hoja1!A:A,Hoja1!G:G,"--",0,1)) -> -- | L18: =_xlfn.XLOOKUP(B18,Hoja1!A:A,Hoja1!H:H,"--",0,1) -> -- | M18: =IF(K18="--",POWER(10,-0.2233*LOG10(I18)-2.901),"--") -> 0.0011971234 | N18: =_xlfn.XLOOKUP(B18,f0_a0!A:A,f0_a0!C:C,0,0,1) -> 4.0819377
A19: EST_18 | B19: C22O | C19: -29.96551 | D19: -71.35111 | E19: 36 | F19: 1228 | G19: -- | H19: 6.4838235 | I19: 6.4838235 | J19: =J18+1 -> 18 | K19: =(_xlfn.XLOOKUP(B19,Hoja1!A:A,Hoja1!G:G,"--",0,1)) -> -- | L19: =_xlfn.XLOOKUP(B19,Hoja1!A:A,Hoja1!H:H,"--",0,1) -> -- | M19: =IF(K19="--",POWER(10,-0.2233*LOG10(I19)-2.901),"--") -> 0.00082740491 | N19: =_xlfn.XLOOKUP(B19,f0_a0!A:A,f0_a0!C:C,0,0,1) -> 1.6562574
A20: EST_19 | B20: C09O | C20: -29.51064 | D20: -71.20036 | E20: 0 | F20: 576 | G20: 5.77 | H20: -- | I20: 5.77 | J20: =J19+1 -> 19 | K20: =(_xlfn.XLOOKUP(B20,Hoja1!A:A,Hoja1!G:G,"--",0,1)) -> -- | L20: =_xlfn.XLOOKUP(B20,Hoja1!A:A,Hoja1!H:H,"--",0,1) -> -- | M20: =IF(K20="--",POWER(10,-0.2233*LOG10(I20)-2.901),"--") -> 0.00084923804 | N20: =_xlfn.XLOOKUP(B20,f0_a0!A:A,f0_a0!C:C,0,0,1) -> 3.0510065
A21: EST_20 | B21: PB15 | C21: -23.208335 | D21: -69.47092 | E21: 0 | F21: 532 | G21: 2.22 | H21: -- | I21: 2.22 | J21: =J20+1 -> 20 | K21: =(_xlfn.XLOOKUP(B21,Hoja1!A:A,Hoja1!G:G,"--",0,1)) -> 0.012 | L21: =_xlfn.XLOOKUP(B21,Hoja1!A:A,Hoja1!H:H,"--",0,1) -> 7.94e-05 | M21: =IF(K21="--",POWER(10,-0.2233*LOG10(I21)-2.901),"--") -> -- | N21: =_xlfn.XLOOKUP(B21,f0_a0!A:A,f0_a0!C:C,0,0,1) -> 3.4503543
A22: EST_21 | B22: CO03 | C22: -30.8389 | D22: -70.6891 | E22: 0 | F22: 639 | G22: 7.79 | H22: -- | I22: 7.79 | J22: =J21+1 -> 21 | K22: =(_xlfn.XLOOKUP(B22,Hoja1!A:A,Hoja1!G:G,"--",0,1)) -> 0.005 | L22: =_xlfn.XLOOKUP(B22,Hoja1!A:A,Hoja1!H:H,"--",0,1) -> 0.00017845 | M22: =IF(K22="--",POWER(10,-0.2233*LOG10(I22)-2.901),"--") -> -- | N22: =_xlfn.XLOOKUP(B22,f0_a0!A:A,f0_a0!C:C,0,0,1) -> 2.3804747
A23: EST_22 | B23: C19O | C23: -30.09348 | D23: -71.36893 | E23: 71 | F23: 1106 | G23: -- | H23: 11.015885 | I23: 11.015885 | J23: =J22+1 -> 22 | K23: =(_xlfn.XLOOKUP(B23,Hoja1!A:A,Hoja1!G:G,"--",0,1)) -> -- | L23: =_xlfn.XLOOKUP(B23,Hoja1!A:A,Hoja1!H:H,"--",0,1) -> -- | M23: =IF(K23="--",POWER(10,-0.2233*LOG10(I23)-2.901),"--") -> 0.00073505031 | N23: =_xlfn.XLOOKUP(B23,f0_a0!A:A,f0_a0!C:C,0,0,1) -> 2.4171959
A24: EST_23 | B24: C33O | C24: -29.91071 | D24: -71.25082 | E24: 30 | F24: 587 | G24: 3.2 | H24: -- | I24: 3.2 | J24: =J23+1 -> 23 | K24: =(_xlfn.XLOOKUP(B24,Hoja1!A:A,Hoja1!G:G,"--",0,1)) -> -- | L24: =_xlfn.XLOOKUP(B24,Hoja1!A:A,Hoja1!H:H,"--",0,1) -> -- | M24: =IF(K24="--",POWER(10,-0.2233*LOG10(I24)-2.901),"--") -> 0.00096872389 | N24: =_xlfn.XLOOKUP(B24,f0_a0!A:A,f0_a0!C:C,0,0,1) -> 2.8545474
A25: EST_24 | B25: MT05 | C25: -33.3919 | D25: -70.7381 | E25: 765 | F25: 496 | G25: 3.08 | H25: -- | I25: 3.08 | J25: =J24+1 -> 24 | K25: =(_xlfn.XLOOKUP(B25,Hoja1!A:A,Hoja1!G:G,"--",0,1)) -> 0.076 | L25: =_xlfn.XLOOKUP(B25,Hoja1!A:A,Hoja1!H:H,"--",0,1) -> −0.00012444 | M25: =IF(K25="--",POWER(10,-0.2233*LOG10(I25)-2.901),"--") -> -- | N25: =_xlfn.XLOOKUP(B25,f0_a0!A:A,f0_a0!C:C,0,0,1) -> 4.0076178
A26: EST_25 | B26: R02M | C26: -33.472778 | D26: -70.659722 | E26: 0 | F26: 724 | G26: -- | H26: 2.30625 | I26: 2.30625 | J26: =J25+1 -> 25 | K26: =(_xlfn.XLOOKUP(B26,Hoja1!A:A,Hoja1!G:G,"--",0,1)) -> -- | L26: =_xlfn.XLOOKUP(B26,Hoja1!A:A,Hoja1!H:H,"--",0,1) -> -- | M26: =IF(K26="--",POWER(10,-0.2233*LOG10(I26)-2.901),"--") -> 0.0010422286 | N26: =_xlfn.XLOOKUP(B26,f0_a0!A:A,f0_a0!C:C,0,0,1) -> 2.0081271
A27: EST_26 | B27: R12M | C27: -33.388686 | D27: -70.621589 | E27: 0 | F27: 311 | G27: 0.99 | H27: -- | I27: 0.99 | J27: =J26+1 -> 26 | K27: =(_xlfn.XLOOKUP(B27,Hoja1!A:A,Hoja1!G:G,"--",0,1)) -> -- | L27: =_xlfn.XLOOKUP(B27,Hoja1!A:A,Hoja1!H:H,"--",0,1) -> -- | M27: =IF(K27="--",POWER(10,-0.2233*LOG10(I27)-2.901),"--") -> 0.001258852 | N27: =_xlfn.XLOOKUP(B27,f0_a0!A:A,f0_a0!C:C,0,0,1) -> 5.3601454
A28: EST_27 | B28: R14M | C28: -33.397111 | D28: -70.546306 | E28: 0 | F28: 635 | G28: -- | H28: 12.403571 | I28: 12.403571 | J28: =J27+1 -> 27 | K28: =(_xlfn.XLOOKUP(B28,Hoja1!A:A,Hoja1!G:G,"--",0,1)) -> -- | L28: =_xlfn.XLOOKUP(B28,Hoja1!A:A,Hoja1!H:H,"--",0,1) -> -- | M28: =IF(K28="--",POWER(10,-0.2233*LOG10(I28)-2.901),"--") -> 0.00071583184 | N28: =_xlfn.XLOOKUP(B28,f0_a0!A:A,f0_a0!C:C,0,0,1) -> 2.3330902
A29: EST_28 | B29: R16M | C29: -33.4 | D29: -70.658639 | E29: 0 | F29: 353 | G29: 0.51 | H29: -- | I29: 0.51 | J29: =J28+1 -> 28 | K29: =(_xlfn.XLOOKUP(B29,Hoja1!A:A,Hoja1!G:G,"--",0,1)) -> -- | L29: =_xlfn.XLOOKUP(B29,Hoja1!A:A,Hoja1!H:H,"--",0,1) -> -- | M29: =IF(K29="--",POWER(10,-0.2233*LOG10(I29)-2.901),"--") -> 0.0014598209 | N29: =_xlfn.XLOOKUP(B29,f0_a0!A:A,f0_a0!C:C,0,0,1) -> 2.9225477
A30: EST_29 | B30: R18M | C30: -33.508417 | D30: -70.748806 | E30: 0 | F30: 379 | G30: 2.7 | H30: -- | I30: 2.7 | J30: =J29+1 -> 29 | K30: =(_xlfn.XLOOKUP(B30,Hoja1!A:A,Hoja1!G:G,"--",0,1)) -> -- | L30: =_xlfn.XLOOKUP(B30,Hoja1!A:A,Hoja1!H:H,"--",0,1) -> -- | M30: =IF(K30="--",POWER(10,-0.2233*LOG10(I30)-2.901),"--") -> 0.0010061818 | N30: =_xlfn.XLOOKUP(B30,f0_a0!A:A,f0_a0!C:C,0,0,1) -> 4.3941768
A31: EST_30 | B31: R19M | C31: -33.698472 | D31: -71.217222 | E31: 0 | F31: 471 | G31: 1.4 | H31: -- | I31: 1.4 | J31: =J30+1 -> 30 | K31: =(_xlfn.XLOOKUP(B31,Hoja1!A:A,Hoja1!G:G,"--",0,1)) -> -- | L31: =_xlfn.XLOOKUP(B31,Hoja1!A:A,Hoja1!H:H,"--",0,1) -> -- | M31: =IF(K31="--",POWER(10,-0.2233*LOG10(I31)-2.901),"--") -> 0.0011651172 | N31: =_xlfn.XLOOKUP(B31,f0_a0!A:A,f0_a0!C:C,0,0,1) -> 3.8222134
A32: EST_31 | B32: R20M | C32: -33.665194 | D32: -70.929333 | E32: 0 | F32: 471 | G32: 1.4 | H32: -- | I32: 1.4 | J32: =J31+1 -> 31 | K32: =(_xlfn.XLOOKUP(B32,Hoja1!A:A,Hoja1!G:G,"--",0,1)) -> -- | L32: =_xlfn.XLOOKUP(B32,Hoja1!A:A,Hoja1!H:H,"--",0,1) -> -- | M32: =IF(K32="--",POWER(10,-0.2233*LOG10(I32)-2.901),"--") -> 0.0011651172 | N32: =_xlfn.XLOOKUP(B32,f0_a0!A:A,f0_a0!C:C,0,0,1) -> 2.478751
A33: EST_32 | B33: R21M | C33: -33.380861 | D33: -70.796167 | E33: 0 | F33: 471 | G33: 1.4 | H33: -- | I33: 1.4 | J33: =J32+1 -> 32 | K33: =(_xlfn.XLOOKUP(B33,Hoja1!A:A,Hoja1!G:G,"--",0,1)) -> -- | L33: =_xlfn.XLOOKUP(B33,Hoja1!A:A,Hoja1!H:H,"--",0,1) -> -- | M33: =IF(K33="--",POWER(10,-0.2233*LOG10(I33)-2.901),"--") -> 0.0011651172 | N33: =_xlfn.XLOOKUP(B33,f0_a0!A:A,f0_a0!C:C,0,0,1) -> 5.2193509
A34: EST_33 | B34: ROC1 | C34: -32.9756 | D34: -71.0156 | E34: 0 | F34: 1951 | G34: 9.9 | H34: -- | I34: 9.9 | J34: =J33+1 -> 33 | K34: =(_xlfn.XLOOKUP(B34,Hoja1!A:A,Hoja1!G:G,"--",0,1)) -> 0.047 | L34: =_xlfn.XLOOKUP(B34,Hoja1!A:A,Hoja1!H:H,"--",0,1) -> 1.255e-05 | M34: =IF(K34="--",POWER(10,-0.2233*LOG10(I34)-2.901),"--") -> -- | N34: =_xlfn.XLOOKUP(B34,f0_a0!A:A,f0_a0!C:C,0,0,1) -> 2.9839397
A35: EST_34 | B35: V01A | C35: -33.053122 | D35: -71.622031 | E35: 0 | F35: 642 | G35: 8.48 | H35: -- | I35: 8.48 | J35: =J34+1 -> 34 | K35: =(_xlfn.XLOOKUP(B35,Hoja1!A:A,Hoja1!G:G,"--",0,1)) -> -- | L35: =_xlfn.XLOOKUP(B35,Hoja1!A:A,Hoja1!H:H,"--",0,1) -> -- | M35: =IF(K35="--",POWER(10,-0.2233*LOG10(I35)-2.901),"--") -> 0.00077927224 | N35: =_xlfn.XLOOKUP(B35,f0_a0!A:A,f0_a0!C:C,0,0,1) -> 2.7574935
A36: EST_35 | B36: V07A | C36: -33.365428 | D36: -71.669036 | E36: 0 | F36: 549 | G36: 5.72 | H36: -- | I36: 5.72 | J36: =J35+1 -> 35 | K36: =(_xlfn.XLOOKUP(B36,Hoja1!A:A,Hoja1!G:G,"--",0,1)) -> -- | L36: =_xlfn.XLOOKUP(B36,Hoja1!A:A,Hoja1!H:H,"--",0,1) -> -- | M36: =IF(K36="--",POWER(10,-0.2233*LOG10(I36)-2.901),"--") -> 0.00085089009 | N36: =_xlfn.XLOOKUP(B36,f0_a0!A:A,f0_a0!C:C,0,0,1) -> 3.4777015
A37: EST_36 | B37: V09A | C37: -33.048061 | D37: -71.6045 | E37: 0 | F37: 317 | G37: 1.61 | H37: -- | I37: 1.61 | J37: =J36+1 -> 36 | K37: =(_xlfn.XLOOKUP(B37,Hoja1!A:A,Hoja1!G:G,"--",0,1)) -> -- | L37: =_xlfn.XLOOKUP(B37,Hoja1!A:A,Hoja1!H:H,"--",0,1) -> -- | M37: =IF(K37="--",POWER(10,-0.2233*LOG10(I37)-2.901),"--") -> 0.0011293168 | N37: =_xlfn.XLOOKUP(B37,f0_a0!A:A,f0_a0!C:C,0,0,1) -> 4.3116963
A38: EST_37 | B38: V16A | C38: -33.590583 | D38: -71.604611 | E38: 0 | F38: 477 | G38: 5.6 | H38: -- | I38: 5.6 | J38: =J37+1 -> 37 | K38: =(_xlfn.XLOOKUP(B38,Hoja1!A:A,Hoja1!G:G,"--",0,1)) -> -- | L38: =_xlfn.XLOOKUP(B38,Hoja1!A:A,Hoja1!H:H,"--",0,1) -> -- | M38: =IF(K38="--",POWER(10,-0.2233*LOG10(I38)-2.901),"--") -> 0.00085492814 | N38: =_xlfn.XLOOKUP(B38,f0_a0!A:A,f0_a0!C:C,0,0,1) -> 7.3998645
A39: EST_38 | B39: V17A | C39: -33.605484 | D39: -71.61432 | E39: 0 | F39: 281 | G39: 0.95 | H39: -- | I39: 0.95 | J39: =J38+1 -> 38 | K39: =(_xlfn.XLOOKUP(B39,Hoja1!A:A,Hoja1!G:G,"--",0,1)) -> -- | L39: =_xlfn.XLOOKUP(B39,Hoja1!A:A,Hoja1!H:H,"--",0,1) -> -- | M39: =IF(K39="--",POWER(10,-0.2233*LOG10(I39)-2.901),"--") -> 0.001270499 | N39: =_xlfn.XLOOKUP(B39,f0_a0!A:A,f0_a0!C:C,0,0,1) -> 5.2237149
A40: EST_39 | B40: V22A | C40: -33.020206 | D40: -71.635775 | E40: 0 | F40: 854 | G40: 8.5 | H40: -- | I40: 8.5 | J40: =J39+1 -> 39 | K40: =(_xlfn.XLOOKUP(B40,Hoja1!A:A,Hoja1!G:G,"--",0,1)) -> -- | L40: =_xlfn.XLOOKUP(B40,Hoja1!A:A,Hoja1!H:H,"--",0,1) -> -- | M40: =IF(K40="--",POWER(10,-0.2233*LOG10(I40)-2.901),"--") -> 0.00077886243 | N40: =_xlfn.XLOOKUP(B40,f0_a0!A:A,f0_a0!C:C,0,0,1) -> 2.1751195
... A47: EST_46 | B47: PB11 | C47: -19.76096 | D47: -69.65582 | E47: 0 | F47: 846 | G47: 0.53 | H47: -- | I47: 0.53 | J47: =J46+1 -> 46 | K47: =(_xlfn.XLOOKUP(B47,Hoja1!A:A,Hoja1!G:G,"--",0,1)) -> -- | L47: =_xlfn.XLOOKUP(B47,Hoja1!A:A,Hoja1!H:H,"--",0,1) -> -- | M47: =IF(K47="--",POWER(10,-0.2233*LOG10(I47)-2.901),"--") -> 0.0014473354 | N47: =_xlfn.XLOOKUP(B47,f0_a0!A:A,f0_a0!C:C,0,0,1) -> 3.045747
A48: EST_47 | B48: V11A | C48: -32.755706 | D48: -70.72522 | E48: 673 | F48: 837 | G48: -- | H48: 2.5954545 | I48: 2.5954545 | J48: =J47+1 -> 47 | K48: =(_xlfn.XLOOKUP(B48,Hoja1!A:A,Hoja1!G:G,"--",0,1)) -> -- | L48: =_xlfn.XLOOKUP(B48,Hoja1!A:A,Hoja1!H:H,"--",0,1) -> -- | M48: =IF(K48="--",POWER(10,-0.2233*LOG10(I48)-2.901),"--") -> 0.0010150937 | N48: =_xlfn.XLOOKUP(B48,f0_a0!A:A,f0_a0!C:C,0,0,1) -> 2.3518358
A49: EST_48 | B49: R05M | C49: -33.442822 | D49: -70.534631 | E49: 0 | F49: 635 | G49: -- | H49: 20.262821 | I49: 20.262821 | J49: =J48+1 -> 48 | K49: =(_xlfn.XLOOKUP(B49,Hoja1!A:A,Hoja1!G:G,"--",0,1)) -> -- | L49: =_xlfn.XLOOKUP(B49,Hoja1!A:A,Hoja1!H:H,"--",0,1) -> -- | M49: =IF(K49="--",POWER(10,-0.2233*LOG10(I49)-2.901),"--") -> 0.00064152548 | N49: =_xlfn.XLOOKUP(B49,f0_a0!A:A,f0_a0!C:C,0,0,1) -> 2.6096981
...

Sheet Hoja2
A1: Frecuencia | B1: C1 | C1: C2 | D1: C3 | E1: C4 | F1: C5 | G1: C6 | H1: C7 | I1: C8 | J1: phiss | K1: phiS2S | L1: tau | M1: sigma
A2: 0.1 | B2: 6.1537054 | C2: 3.414617 | D2: 0.33214013 | E2: -1.3999073 | F2: -0.063188958 | G2: 0.043542811 | H2: 0.000551852 | I2: -0.26545305 | J2: 1.4643227 | K2: 0.4621342 | L2: 0.7947816 | M2: =SQRT((J2^2)+(K2^2)+(L2^2)) -> 1.7290132
A3: 0.4 | B3: 9.4300988 | C3: 2.3621695 | D3: -0.65339767 | E3: -1.3039283 | F3: -0.062252295 | G3: 0.03559399 | H3: 6.15e-05 | I3: -0.36708021 | J3: 0.87086283 | K3: 0.57327086 | L3: 0.87925527 | M3: =SQRT((J3^2)+(K3^2)+(L3^2)) -> 1.3638663
A4: 0.7 | B4: 10.298514 | C4: 2.1185046 | D4: -0.5974294 | E4: -0.97191724 | F4: -0.05352077 | G4: -0.032056486 | H4: 0.000190883 | I4: -0.59173144 | J4: 0.58088077 | K4: 0.6193025 | L4: 0.66874815 | M4: =SQRT((J4^2)+(K4^2)+(L4^2)) -> 1.0808248
A5: 1 | B5: 9.8766939 | C5: 1.8478816 | D5: -0.42466865 | E5: -0.93936482 | F5: -0.043213644 | G5: -0.018788271 | H5: -0.000294636 | I5: -0.85225587 | J5: 0.47380202 | K5: 0.69624502 | L5: 0.49558559 | M5: =SQRT((J5^2)+(K5^2)+(L5^2)) -> 0.97716455
A6: 2 | B6: 9.8359149 | C6: 1.7700879 | D6: -0.27015284 | E6: -0.520808 | F6: -0.016502227 | G6: -0.072505905 | H6: -0.00105135 | I6: -0.98658771 | J6: 0.39533744 | K6: 0.62804694 | L6: 0.37387482 | M6: =SQRT((J6^2)+(K6^2)+(L6^2)) -> 0.83097354
A7: 3 | B7: 10.728608 | C7: 2.0809767 | D7: -0.18953109 | E7: -0.12304836 | F7: 0.010369822 | G7: -0.16841607 | H7: -0.000398675 | I7: -0.92786364 | J7: 0.36482365 | K7: 0.58558431 | L7: 0.34904404 | M7: =SQRT((J7^2)+(K7^2)+(L7^2)) -> 0.77319922
A8: 4 | B8: 11.057335 | C8: 2.3520618 | D8: -0.13078088 | E8: 0.27873768 | F8: 0.044982393 | G8: -0.24347257 | H8: -0.00065971 | I8: -0.83354697 | J8: 0.34865241 | K8: 0.56496815 | L8: 0.36923598 | M8: =SQRT((J8^2)+(K8^2)+(L8^2)) -> 0.75965961
A9: 5 | B9: 11.443028 | C9: 2.3191468 | D9: -0.11157543 | E9: 0.21903317 | F9: 0.069593027 | G9: -0.24750732 | H9: -0.000703964 | I9: -0.78839391 | J9: 0.33395335 | K9: 0.57249765 | L9: 0.39113605 | M9: =SQRT((J9^2)+(K9^2)+(L9^2)) -> 0.76958808
A10: 6 | B10: 11.986773 | C10: 2.5183259 | D10: -0.088754142 | E10: 0.35232521 | F10: 0.10630074 | G10: -0.29210619 | H10: -0.000446987 | I10: -0.70619959 | J10: 0.32438787 | K10: 0.57062253 | L10: 0.41954064 | M10: =SQRT((J10^2)+(K10^2)+(L10^2)) -> 0.779007
A11: 7 | B11: 12.145706 | C11: 2.3845156 | D11: -0.093651238 | E11: 0.20396246 | F11: 0.12814653 | G11: -0.27311181 | H11: -0.000612196 | I11: -0.61407597 | J11: 0.31577157 | K11: 0.57887939 | L11: 0.44762331 | M11: =SQRT((J11^2)+(K11^2)+(L11^2)) -> 0.79698159
A12: 8 | B12: 12.060759 | C12: 2.2121372 | D12: -0.10052206 | E12: 0.038515013 | F12: 0.14596617 | G12: -0.24319969 | H12: -0.001007766 | I12: -0.54101402 | J12: 0.30013266 | K12: 0.61181366 | L12: 0.47735298 | M12: =SQRT((J12^2)+(K12^2)+(L12^2)) -> 0.8320225
A13: 9 | B13: 12.181342 | C13: 2.074403 | D13: -0.11798504 | E13: -0.161521 | F13: 0.16295887 | G13: -0.21607264 | H13: -0.001234397 | I13: -0.50399207 | J13: 0.29278408 | K13: 0.64636531 | L13: 0.50396169 | M13: =SQRT((J13^2)+(K13^2)+(L13^2)) -> 0.87033787
... A18: 45 | B18: 13.291095 | C18: 2.0454332 | D18: -0.18634998 | E18: -0.77383945 | F18: 0.24057764 | G18: -0.26735209 | H18: 0.002510851 | I18: 0.16799468 | J18: 0.44658212 | K18: 1.296064 | L18: 0.66552198 | M18: =SQRT((J18^2)+(K18^2)+(L18^2)) -> 1.523856

Sheet TablaAnexo31
F1: ID Ev | G1: Evento | H1: Lat Ev [°] | I1: Long Ev [°] | J1: Mw | M1: ID Est | N1: Est | O1: Lat Est [°] | P1: Long Est [°] | Q1: Vs30 [m/s] | R1: f0 [hz] | S1: Kappa (s)
F2: EV_1 | G2: 2012-03-03T11-1-47_Mw_5,6 | H2: -30.189 | I2: -71.448 | J2: 5.6 | M2: EST_1 | N2: GO04 | O2: -30.1727 | P2: -70.7993 | Q2: 405 | R2: 1.64 | S2: 0.048
F3: EV_2 | G3: 2012-04-01T7-31-36_Mw_5,2 | H3: -23.056 | I3: -69.316 | J3: 5.2 | M3: EST_2 | N3: PB06 | O3: -22.7058 | P3: -69.57188 | Q3: 736 | R3: 7.94 | S3: 0.006
F4: EV_3 | G4: 2014-03-16T21-16-29_Mw_6,7 | H4: -19.965 | I4: -70.814 | J4: 6.7 | M4: EST_3 | N4: T03A | O4: -20.23034 | P4: -70.14592 | Q4: 635 | R4: 7.01 | S4: 0.00081311349
F5: EV_4 | G5: 2015-09-17T1-41-5_Mw_6,5 | H5: -31.113 | I5: -71.651 | J5: 6.5 | M5: EST_4 | N5: T06A | O5: -20.2142 | P5: -70.13789 | Q5: 276 | R5: 1.67 | S5: 0.0011201274
F6: EV_5 | G6: 2015-09-17T10-12-53_Mw_5,3 | H6: -30.536 | I6: -71.632 | J6: 5.3 | M6: EST_5 | N6: C10O | O6: -30.23387 | P6: -71.08159 | Q6: 517 | R6: 6.5 | S6: 0.00082694466
F7: EV_6 | G7: 2015-09-17T10-31-25_Mw_5,0 | H7: -30.933 | I7: -71.459 | J7: 5 | M7: EST_6 | N7: C11O | O7: -30.696472 | P7: -70.958889 | Q7: 402 | R7: 3.22 | S7: 0.00096737706
F8: EV_7 | G8: 2015-09-17T12-58-8_Mw_4,9 | H8: -30.694 | I8: -71.559 | J8: 4.9 | M8: EST_7 | N8: T08A | O8: -20.27016 | P8: -70.09414 | Q8: 680 | R8: 14.35 | S8: 0.00069290703
F9: EV_8 | G9: 2015-09-17T13-32-26_Mw_6,0 | H9: -32.143 | I9: -72.173 | J9: 6 | M9: EST_8 | N9: C23O | O9: -31.783711 | P9: -70.969739 | Q9: 751 | R9: 2.1 | S9: 0.0010642617
F10: EV_9 | G10: 2015-09-17T16-46-23_Mw_5,0 | H10: -31.504 | I10: -71.737 | J10: 5 | M10: EST_9 | N10: C26O | O10: -30.25898 | P10: -71.49046 | Q10: 364 | R10: 1.87 | S10: 0.0010921889
F11: EV_10 | G11: 2015-09-17T16-52-20_Mw_5,3 | H11: -29.935 | I11: -71.961 | J11: 5.3 | M11: EST_10 | N11: C32O | O11: -30.854861 | P11: -70.707333 | Q11: 578 | R11: 6.51 | S11: 0.00082666084
F12: EV_11 | G12: 2015-09-17T16-8-9_Mw_5,3 | H12: -29.854 | I12: -70.485 | J12: 5.3 | M12: EST_11 | N12: R13M | O12: -33.215583 | P12: -70.766861 | Q12: 401 | R12: 1.31 | S12: 0.0011825331
F13: EV_12 | G13: 2015-09-17T17-32-20_Mw_4,8 | H13: -30.684 | I13: -71.614 | J13: 4.8 | M13: EST_12 | N13: V15A | O13: -32.914889 | P13: -71.232592 | Q13: 549 | R13: 5.72 | S13: 0.00085089009
... F71: EV_70 | G71: 2015-09-24T16-13-25_Mw_5,4 | H71: -30.705 | I71: -71.398 | J71: 5.4 | M71: EST_70 | N71: M10L | O71: -35.843056 | P71: -72.63 | Q71: 402 | R71: 5.4055556 | S71: 0.00086170131
F72: EV_71 | G72: 2015-09-24T7-14-44_Mw_4,8 | H72: -20.214 | I72: -69.15 | J72: 4.8 | M72: EST_71 | N72: T12A | O72: -20.07067 | P72: -69.21722 | Q72: 732 | R72: 10.01 | S72: −0.006
F73: EV_72 | G73: 2015-09-25T11-47-8_Mw_4,7 | H73: -31.561 | I73: -71.806 | J73: 4.7 | M73: EST_72 | N73: L02R | O73: -39.832194 | P73: -73.201028 | Q73: 229 | R73: 1.04 | S73: 0.0012450777
F74: EV_73 | G74: 2015-09-25T3-21-57_Mw_5,3 | H74: -20.91 | I74: -69.221 | J74: 5.3 | M74: EST_73 | N74: A04C | O74: -27.29958 | P74: -70.421317 | Q74: 534 | R74: 1.13 | S74: 0.0012222149
F75: EV_74 | G75: 2015-09-26T11-15-29_Mw_4,6 | H75: -31.828 | I75: -71.952 | J75: 4.6 | M75: EST_74 | N75: A06C | O75: -27.3494 | P75: -70.34776 | Q75: 483 | R75: 5.81 | S75: 0.00084792896
F76: EV_75 | G76: 2015-09-26T2-51-18_Mw_6,3 | H76: -30.794 | I76: -71.418 | J76: 6.3 | M76: EST_75 | N76: A28C | O76: -27.46644 | P76: -70.26543 | Q76: 522 | R76: 6.9 | S76: 0.0008159903
F77: EV_76 | G77: 2015-09-27T21-4-45_Mw_5,3 | H77: -31.669 | I77: -71.701 | J77: 5.3 | M77: EST_76 | N77: CO05 | O77: -29.91864 | P77: -71.23841 | Q77: 773 | R77: 0.92222222 | S77: 0.001278946
F78: EV_77 | G78: 2015-09-27T8-28-36_Mw_4,6 | H78: -30.732 | I78: -71.473 | J78: 4.6 | M78: EST_77 | N78: FAR1 | O78: -33.3377 | P78: -70.2994 | Q78: 681 | R78: 5.55 | S78: 0.019
F79: EV_78 | G79: 2015-09-28T15-28-4_Mw_6,0 | H79: -23.875 | I79: -67.121 | J79: 6 | M79: EST_78 | N79: A10F | O79: -25.41106 | P79: -70.48425 | Q79: 517 | R79: 6.5 | S79: 0.00082694466
F80: EV_79 | G80: 2015-09-30T18-21-17_Mw_4,7 | H80: -30.638 | I80: -71.722 | J80: 4.7 | M80: EST_79 | N80: A21F | O80: -25.40762 | P80: -70.48847 | Q80: 517 | R80: 6.5 | S80: 0.00082694466
F81: EV_80 | G81: 2015-09-30T2-0-3_Mw_4,9 | H81: -30.663 | I81: -71.724 | J81: 4.9 | M81: EST_80 | N81: PB02 | O81: -21.31973 | P81: -69.89603 | Q81: 746 | R81: 1.29 | S81: 0.0011866027
F82: EV_81 | G82: 2015-10-01T2-6-22_Mw_4,8 | H82: -30.719 | I82: -71.428 | J82: 4.8 | M82: EST_81 | N82: LMEL | O82: -33.8476 | P82: -70.2075 | Q82: 808 | R82: 5 | S82: 0.045
F83: EV_82 | G83: 2015-10-02T16-22-47_Mw_4,9 | H83: -30.579 | I83: -71.6 | J83: 4.9 | M83: EST_82 | N83: L05L | O83: -41.15378 | P83: -73.41754 | Q83: 255 | R83: 1.41 | S83: 0.0011632669
F84: EV_83 | G84: 2015-10-02T8-28-8_Mw_4,9 | H84: -36.488 | I84: -71.728 | J84: 4.9 | M84: EST_83 | N84: L09L | O84: -41.865269 | P84: -73.826139 | Q84: 182 | R84: 2.85 | S84: 0.00099410702
... F185: EV_184 | G185: 2016-02-10T0-33-4_Mw_6,4 | H185: -30.634 | I185: -71.649 | J185: 6.4 | M185: EST_184 | N185: LR04 | O185: -39.88019 | P185: -73.425822 | Q185: 457 | R185: 3.6 | S185: 0.00094357766
F186: EV_185 | G186: 2016-02-12T22-32-5_Mw_5,0 | H186: -19.943 | I186: -70.311 | J186: 5
F187: EV_186 | G187: 2014-04-03T5-34-33_Mw_4,6 | H187: -20.466 | I187: -70.573 | J187: 4.6
F188: EV_187 | G188: 2016-02-19T5-33-8_Mw_5,4 | H188: -30.587 | I188: -71.695 | J188: 5.4
F189: EV_188 | G189: 2016-02-20T18-23-1_Mw_4,9 | H189: -32.499 | I189: -70.013 | J189: 4.9
F190: EV_189 | G190: 2016-02-22T6-37-1_Mw_6,0 | H190: -30.488 | I190: -72.227 | J190: 6
F191: EV_190 | G191: 2012-11-13T3-11-25_Mw_5,1 | H191: -20.54 | I191: -69.03 | J191: 5.1
F192: EV_191 | G192: 2014-04-03T5-51-44_Mw_5,5 | H192: -20.756 | I192: -70.425 | J192: 5.5
F193: EV_192 | G193: 2016-02-24T17-2-4_Mw_4,7 | H193: -29.957 | I193: -71.663 | J193: 4.7
F194: EV_193 | G194: 2014-04-03T5-51-45_Mw_5,5 | H194: -20.769 | I194: -70.437 | J194: 5.5
F195: EV_194 | G195: 2016-02-24T19-10-1_Mw_4,7 | H195: -29.799 | I195: -71.478 | J195: 4.7
F196: EV_195 | G196: 2016-02-25T11-27-53_Mw_4,7 | H196: -30.772 | I196: -71.384 | J196: 4.7
F197: EV_196 | G197: 2016-02-25T15-35-7_Mw_5,3 | H197: -23.055 | I197: -69.045 | J197: 5.3
...

Sheet f0_a0
A1: Est | B1: f0 | C1: A0 | D1: f0_comp | E1: error
A2: A01C | B2: 9.8 | C2: 1.9097708 | D2: =_xlfn.XLOOKUP(A2,ESTACIONES!B:B,ESTACIONES!I:I,0,0,1) -> 4.9590909 | E2: =B2-D2 -> 4.8409091
A3: A03C | B3: 4.2725 | C3: 2.060802 | D3: =_xlfn.XLOOKUP(A3,ESTACIONES!B:B,ESTACIONES!I:I,0,0,1) -> 6.71 | E3: =B3-D3 -> -2.4375
A4: A04C | B4: 5.815 | C4: 2.3252025 | D4: =_xlfn.XLOOKUP(A4,ESTACIONES!B:B,ESTACIONES!I:I,0,0,1) -> 1.13 | E4: =B4-D4 -> 4.685
A5: A04P | B5: 20.49375 | C5: 3.4269529 | D5: =_xlfn.XLOOKUP(A5,ESTACIONES!B:B,ESTACIONES!I:I,0,0,1) -> 1.6 | E5: =B5-D5 -> 18.89375
A6: A05C | B6: 4.9125 | C6: 6.0209362 | D6: =_xlfn.XLOOKUP(A6,ESTACIONES!B:B,ESTACIONES!I:I,0,0,1) -> 6.3 | E6: =B6-D6 -> -1.3875
A7: A05P | B7: 2.015625 | C7: 2.495066 | D7: =_xlfn.XLOOKUP(A7,ESTACIONES!B:B,ESTACIONES!I:I,0,0,1) -> 1.2 | E7: =B7-D7 -> 0.815625
A8: A06C | B8: 14.085 | C8: 2.6768062 | D8: =_xlfn.XLOOKUP(A8,ESTACIONES!B:B,ESTACIONES!I:I,0,0,1) -> 5.81 | E8: =B8-D8 -> 8.275
A9: A06P | B9: 1.9142857 | C9: 2.7587909 | D9: =_xlfn.XLOOKUP(A9,ESTACIONES!B:B,ESTACIONES!I:I,0,0,1) -> 2.5 | E9: =B9-D9 -> -0.58571429
A10: A07C | B10: 2.5602941 | C10: 6.0324256 | D10: =_xlfn.XLOOKUP(A10,ESTACIONES!B:B,ESTACIONES!I:I,0,0,1) -> 2.51 | E10: =B10-D10 -> 0.050294118
A11: A07P | B11: 1.165 | C11: 2.6550997 | D11: =_xlfn.XLOOKUP(A11,ESTACIONES!B:B,ESTACIONES!I:I,0,0,1) -> 1.2 | E11: =B11-D11 -> -0.035
A12: A07Y | B12: 0.35 | C12: 5.886967 | D12: =_xlfn.XLOOKUP(A12,ESTACIONES!B:B,ESTACIONES!I:I,0,0,1) -> 0.33 | E12: =B12-D12 -> 0.02
A13: A08C | B13: 27.255 | C13: 2.1949899 | D13: =_xlfn.XLOOKUP(A13,ESTACIONES!B:B,ESTACIONES!I:I,0,0,1) -> 14.65 | E13: =B13-D13 -> 12.605
... A185: VA05 | B185: 2.3375 | C185: 3.1397551 | D185: =_xlfn.XLOOKUP(A185,ESTACIONES!B:B,ESTACIONES!I:I,0,0,1) -> 2.46 | E185: =B185-D185 -> -0.1225

Sheet Hoja1
A1: Station | B1: VS30 | C1: Latitude | D1: Longitude | E1: N | F1: distance | G1: k0 | H1: kR
A2: AP01 | B2: 355 | C2: −18.3708 | D2: −70.3419 | E2: 70 | F2: 293 | G2: 0.058 | H2: 1.923e-05
A3: PB12 | B3: 599 | C3: −18.6141 | D3: −70.3281 | E3: 89 | F3: 305 | G3: 0.051 | H3: −0.00006172
A4: PB13 | B4: 510 | C4: −18.3359 | D4: −69.5016 | E4: 17 | F4: 269 | G4: 0.057 | H4: −0.00000632
A5: T11A | B5: 346 | C5: −19.3124 | D5: −69.4273 | E5: 28 | F5: 400 | G5: 0.053 | H5: −0.00005335
A6: T10A | B6: 336 | C6: −19.9954 | D6: −69.767 | E6: 45 | F6: 400 | G6: 0.038 | H6: −0.00000874
A7: GO01 | B7: 973 | C7: −19.6685 | D7: −69.1942 | E7: 90 | F7: 316 | G7: 0.057 | H7: 0.00023215
A8: T09A | B8: 1584 | C8: −19.5957 | D8: −70.2109 | E8: 10 | F8: 169 | G8: 0.012 | H8: 0.00014141
A9: T12A | B9: 732 | C9: −20.0707 | D9: −69.2172 | E9: 13 | F9: 182 | G9: −0.006 | H9: 0.00033606
A10: TA01 | B10: 566 | C10: −20.5656 | D10: −70.1807 | E10: 83 | F10: 265 | G10: 0.067 | H10: −0.00012584
A11: T13A | B11: 378 | C11: −20.4963 | D11: −69.3375 | E11: 17 | F11: 228 | G11: 0.058 | H11: −0.00014154
A12: T07A | B12: 326 | C12: −20.2562 | D12: −69.7859 | E12: 50 | F12: 400 | G12: 0.058 | H12: −0.00000147
A13: T05A | B13: 1020 | C13: −20.2098 | D13: −70.1502 | E13: 20 | F13: 151 | G13: 0.025 | H13: 2.688e-05
A14: TA02 | B14: 489 | C14: −20.2704 | D14: −70.1311 | E14: 25 | F14: 254 | G14: 0.063 | H14: −0.00011208
A15: PB03 | B15: 711 | C15: −22.0485 | D15: −69.7531 | E15: 79 | F15: 309 | G15: 0.016 | H15: 8.188e-05
A16: PB06 | B16: 736 | C16: −22.7058 | D16: −69.5719 | E16: 77 | F16: 376 | G16: 0.006 | H16: 0.00014789
A17: PB05 | B17: 773 | C17: −22.8528 | D17: −70.2024 | E17: 39 | F17: 373 | G17: 0.009 | H17: 0.00011721
A18: PB15 | B18: 532 | C18: −23.2083 | D18: −69.4709 | E18: 38 | F18: 355 | G18: 0.012 | H18: 7.94e-05
A19: PB10 | B19: 790 | C19: −23.5134 | D19: −70.5541 | E19: 46 | F19: 400 | G19: 0.055 | H19: 3.221e-05
A20: GO02 | B20: 820 | C20: −25.1626 | D20: −69.5904 | E20: 11 | F20: 338 | G20: 0.064 | H20: −0.00000848
A21: GO03 | B21: 908 | C21: −27.5937 | D21: −70.2347 | E21: 18 | F21: 336 | G21: 0.033 | H21: −0.00001488
A22: TLL | B22: 1003 | C22: −30.1696 | D22: −70.8054 | E22: 15 | F22: 265 | G22: 0.021 | H22: 8.948e-05
A23: GO04 | B23: 405 | C23: −30.1727 | D23: −70.7993 | E23: 30 | F23: 295 | G23: 0.048 | H23: 8.616e-05
A24: CO03 | B24: 704 | C24: −30.8389 | D24: −70.6891 | E24: 7 | F24: 251 | G24: 0.005 | H24: 0.00017845
A25: VA03 | B25: 485 | C25: −32.7637 | D25: −70.5508 | E25: 11 | F25: 255 | G25: 0.052 | H25: 0.00010649
A26: ROC1 | B26: 1951 | C26: −32.9759 | D26: −71.0156 | E26: 51 | F26: 297 | G26: 0.047 | H26: 1.255e-05
A27: MT02 | B27: 923 | C27: −33.2591 | D27: −71.1377 | E27: 13 | F27: 289 | G27: 0.037 | H27: −0.00008515
A28: FAR1 | B28: 681 | C28: −33.3377 | D28: −70.2994 | E28: 28 | F28: 275 | G28: 0.019 | H28: 0.00011665
A29: LMEL | B29: 808 | C29: −33.8476 | D29: −70.2034 | E29: 30 | F29: 287 | G29: 0.045 | H29: 0.00011123
A30: MT05 | B30: 496 | C30: −33.3919 | D30: −70.7381 | E30: 11 | F30: 273 | G30: 0.076 | H30: −0.00012444
A31: ANTU | B31: 621 | C31: −33.5691 | D31: −70.6335 | E31: 31 | F31: 242 | G31: 0.036 | H31: 2.185e-05
A32: DG01 | B32: 298 | C32: −33.4563 | D32: −70.6624 | E32: 16 | F32: 269 | G32: 0.053 | H32: 2.272e-05
A33: BO02 | B33: 553 | C33: −34.7924 | D33: −70.7814 | E33: 10 | F33: 279 | G33: 0.073 | H33: −0.00006234
A34: GO05 | B34: 536 | C34: −35.0099 | D34: −71.9303 | E34: 31 | F34: 287 | G34: 0.066 | H34: −0.00010849
A35: CCH2 | B35: 403 | C35: −36.603 | D35: −72.0778 | E35: 37 | F35: 301 | G35: 0.073 | H35: 0.00010649
A36: BI03 | B36: 269 | C36: −36.8438 | D36: −73.0258 | E36: 9 | F36: 259 | G36: 0.0931 | H36: −0.00013426
A37: CCSP | B37: 236 | C37: −36.8442 | D37: −72.7112 | E37: 26 | F37: 229 | G37: 0.05 | H37: 7.511e-05

Sheet L y W
A1: id event | B1: L(km) | C1: W(km)
A2: 1 | B2: 5.564165 | C2: 5.8479008
A3: 2 | B3: 0 | C3: 0
A4: 3 | B4: 0 | C4: 0
A5: 4 | B5: 0 | C5: 0
A6: 5 | B6: #N/A | C6: #N/A
A7: 6 | B7: 0 | C7: 0
A8: 7 | B8: 30.352887 | C8: 19.453601
A9: 8 | B9: 30.352887 | C9: 19.453601
A10: 9 | B10: 30.352887 | C10: 19.453601
A11: 10 | B11: 0 | C11: 0
A12: 11 | B12: 9.7948999 | C12: 8.7297137
A13: 12 | B13: 26.025555 | C13: 13.409111
A14: 13 | B14: 26.025555 | C14: 13.409111
A15: 14 | B15: 11.282361 | C15: 9.6493931
A16: 15 | B16: 0 | C16: 0
A17: 16 | B17: 0 | C17: 0
